local_db is up-to-date
Recreating flask-rest-api ... 
[1A[2KRecreating flask-rest-api ... [32mdone[0m[1BRecreating scanner        ... 
[1A[2KRecreating scanner        ... [32mdone[0m[1BAttaching to local_db, flask-rest-api, scanner
[33mlocal_db   |[0m The files belonging to this database system will be owned by user "postgres".
[33mlocal_db   |[0m This user must also own the server process.
[33mlocal_db   |[0m 
[33mlocal_db   |[0m The database cluster will be initialized with locale "en_US.utf8".
[33mlocal_db   |[0m The default database encoding has accordingly been set to "UTF8".
[33mlocal_db   |[0m The default text search configuration will be set to "english".
[33mlocal_db   |[0m 
[33mlocal_db   |[0m Data page checksums are disabled.
[33mlocal_db   |[0m 
[33mlocal_db   |[0m fixing permissions on existing directory /var/lib/postgresql/data ... ok
[33mlocal_db   |[0m creating subdirectories ... ok
[33mlocal_db   |[0m selecting dynamic shared memory implementation ... posix
[33mlocal_db   |[0m selecting default max_connections ... 100
[33mlocal_db   |[0m selecting default shared_buffers ... 128MB
[33mlocal_db   |[0m selecting default time zone ... Etc/UTC
[33mlocal_db   |[0m creating configuration files ... ok
[33mlocal_db   |[0m running bootstrap script ... ok
[33mlocal_db   |[0m performing post-bootstrap initialization ... ok
[33mlocal_db   |[0m syncing data to disk ... ok
[33mlocal_db   |[0m 
[33mlocal_db   |[0m 
[33mlocal_db   |[0m Success. You can now start the database server using:
[33mlocal_db   |[0m 
[33mlocal_db   |[0m     pg_ctl -D /var/lib/postgresql/data -l logfile start
[33mlocal_db   |[0m 
[33mlocal_db   |[0m initdb: warning: enabling "trust" authentication for local connections
[33mlocal_db   |[0m initdb: hint: You can change this by editing pg_hba.conf or using the option -A, or --auth-local and --auth-host, the next time you run initdb.
[33mlocal_db   |[0m waiting for server to start....2023-12-20 22:11:53.773 UTC [48] LOG:  starting PostgreSQL 16.1 (Debian 16.1-1.pgdg120+1) on aarch64-unknown-linux-gnu, compiled by gcc (Debian 12.2.0-14) 12.2.0, 64-bit
[33mlocal_db   |[0m 2023-12-20 22:11:53.780 UTC [48] LOG:  listening on Unix socket "/var/run/postgresql/.s.PGSQL.5432"
[33mlocal_db   |[0m 2023-12-20 22:11:53.806 UTC [51] LOG:  database system was shut down at 2023-12-20 22:11:51 UTC
[33mlocal_db   |[0m 2023-12-20 22:11:53.833 UTC [48] LOG:  database system is ready to accept connections
[33mlocal_db   |[0m  done
[33mlocal_db   |[0m server started
[33mlocal_db   |[0m CREATE DATABASE
[33mlocal_db   |[0m 
[33mlocal_db   |[0m 
[33mlocal_db   |[0m /usr/local/bin/docker-entrypoint.sh: running /docker-entrypoint-initdb.d/init.sql
[33mlocal_db   |[0m CREATE TABLE
[33mlocal_db   |[0m psql:/docker-entrypoint-initdb.d/init.sql:12: NOTICE:  Database user_credentials created
[33mlocal_db   |[0m DO
[33mlocal_db   |[0m CREATE TABLE
[33mlocal_db   |[0m CREATE TABLE
[33mlocal_db   |[0m INSERT 0 1
[33mlocal_db   |[0m INSERT 0 1
[33mlocal_db   |[0m INSERT 0 1
[33mlocal_db   |[0m INSERT 0 1
[33mlocal_db   |[0m INSERT 0 1
[33mlocal_db   |[0m INSERT 0 1
[33mlocal_db   |[0m GRANT
[33mlocal_db   |[0m GRANT
[33mlocal_db   |[0m GRANT
[33mlocal_db   |[0m 
[33mlocal_db   |[0m 
[33mlocal_db   |[0m 2023-12-20 22:11:55.301 UTC [48] LOG:  received fast shutdown request
[33mlocal_db   |[0m waiting for server to shut down....2023-12-20 22:11:55.308 UTC [48] LOG:  aborting any active transactions
[33mlocal_db   |[0m 2023-12-20 22:11:55.320 UTC [48] LOG:  background worker "logical replication launcher" (PID 54) exited with exit code 1
[33mlocal_db   |[0m 2023-12-20 22:11:55.322 UTC [49] LOG:  shutting down
[33mlocal_db   |[0m 2023-12-20 22:11:55.328 UTC [49] LOG:  checkpoint starting: shutdown immediate
[33mlocal_db   |[0m 2023-12-20 22:11:55.811 UTC [49] LOG:  checkpoint complete: wrote 946 buffers (5.8%); 0 WAL file(s) added, 0 removed, 0 recycled; write=0.097 s, sync=0.317 s, total=0.489 s; sync files=311, longest=0.300 s, average=0.002 s; distance=4311 kB, estimate=4311 kB; lsn=0/1920768, redo lsn=0/1920768
[33mlocal_db   |[0m 2023-12-20 22:11:55.854 UTC [48] LOG:  database system is shut down
[33mlocal_db   |[0m  done
[33mlocal_db   |[0m server stopped
[33mlocal_db   |[0m 
[33mlocal_db   |[0m PostgreSQL init process complete; ready for start up.
[33mlocal_db   |[0m 
[33mlocal_db   |[0m 2023-12-20 22:11:56.064 UTC [1] LOG:  starting PostgreSQL 16.1 (Debian 16.1-1.pgdg120+1) on aarch64-unknown-linux-gnu, compiled by gcc (Debian 12.2.0-14) 12.2.0, 64-bit
[33mlocal_db   |[0m 2023-12-20 22:11:56.067 UTC [1] LOG:  listening on IPv4 address "0.0.0.0", port 5432
[33mlocal_db   |[0m 2023-12-20 22:11:56.067 UTC [1] LOG:  listening on IPv6 address "::", port 5432
[33mlocal_db   |[0m 2023-12-20 22:11:56.079 UTC [1] LOG:  listening on Unix socket "/var/run/postgresql/.s.PGSQL.5432"
[33mlocal_db   |[0m 2023-12-20 22:11:56.102 UTC [66] LOG:  database system was shut down at 2023-12-20 22:11:55 UTC
[33mlocal_db   |[0m 2023-12-20 22:11:56.131 UTC [1] LOG:  database system is ready to accept connections
[33mlocal_db   |[0m 2023-12-20 22:12:19.385 UTC [1] LOG:  received fast shutdown request
[33mlocal_db   |[0m 2023-12-20 22:12:19.393 UTC [1] LOG:  aborting any active transactions
[33mlocal_db   |[0m 2023-12-20 22:12:19.411 UTC [1] LOG:  background worker "logical replication launcher" (PID 69) exited with exit code 1
[33mlocal_db   |[0m 2023-12-20 22:12:19.411 UTC [64] LOG:  shutting down
[33mlocal_db   |[0m 2023-12-20 22:12:19.417 UTC [64] LOG:  checkpoint starting: shutdown immediate
[33mlocal_db   |[0m 2023-12-20 22:12:19.477 UTC [64] LOG:  checkpoint complete: wrote 29 buffers (0.2%); 0 WAL file(s) added, 0 removed, 0 recycled; write=0.014 s, sync=0.027 s, total=0.066 s; sync files=10, longest=0.024 s, average=0.003 s; distance=132 kB, estimate=132 kB; lsn=0/19418C8, redo lsn=0/19418C8
[33mlocal_db   |[0m 2023-12-20 22:12:19.504 UTC [1] LOG:  database system is shut down
[33mlocal_db   |[0m 
[33mlocal_db   |[0m PostgreSQL Database directory appears to contain a database; Skipping initialization
[33mlocal_db   |[0m 
[33mlocal_db   |[0m 2023-12-20 22:13:34.972 UTC [1] LOG:  starting PostgreSQL 16.1 (Debian 16.1-1.pgdg120+1) on aarch64-unknown-linux-gnu, compiled by gcc (Debian 12.2.0-14) 12.2.0, 64-bit
[33mlocal_db   |[0m 2023-12-20 22:13:34.973 UTC [1] LOG:  listening on IPv4 address "0.0.0.0", port 5432
[33mlocal_db   |[0m 2023-12-20 22:13:34.973 UTC [1] LOG:  listening on IPv6 address "::", port 5432
[33mlocal_db   |[0m 2023-12-20 22:13:34.990 UTC [1] LOG:  listening on Unix socket "/var/run/postgresql/.s.PGSQL.5432"
[33mlocal_db   |[0m 2023-12-20 22:13:35.066 UTC [31] LOG:  database system was shut down at 2023-12-20 22:12:19 UTC
[33mlocal_db   |[0m 2023-12-20 22:13:35.095 UTC [1] LOG:  database system is ready to accept connections
[33mlocal_db   |[0m 2023-12-20 22:18:35.167 UTC [29] LOG:  checkpoint starting: time
[33mlocal_db   |[0m 2023-12-20 22:18:40.934 UTC [29] LOG:  checkpoint complete: wrote 4 buffers (0.0%); 0 WAL file(s) added, 0 removed, 0 recycled; write=0.302 s, sync=0.028 s, total=5.769 s; sync files=3, longest=0.024 s, average=0.010 s; distance=0 kB, estimate=0 kB; lsn=0/19419B0, redo lsn=0/1941978
[33mlocal_db   |[0m 2023-12-20 22:28:49.636 UTC [33] WARNING:  autovacuum worker took too long to start; canceled
[33mlocal_db   |[0m 2023-12-20 22:29:25.586 UTC [76] WARNING:  autovacuum worker started without a worker entry
[33mlocal_db   |[0m 2023-12-20 22:37:57.519 UTC [33] WARNING:  autovacuum worker took too long to start; canceled
[33mlocal_db   |[0m 2023-12-20 22:38:27.613 UTC [96] WARNING:  autovacuum worker started without a worker entry
[33mlocal_db   |[0m 2023-12-20 22:40:16.230 UTC [33] WARNING:  autovacuum worker took too long to start; canceled
[33mlocal_db   |[0m 2023-12-20 22:44:27.506 UTC [33] WARNING:  autovacuum worker took too long to start; canceled
[33mlocal_db   |[0m 2023-12-20 22:45:37.769 UTC [97] WARNING:  autovacuum worker started without a worker entry
[33mlocal_db   |[0m 2023-12-20 22:47:38.328 UTC [101] WARNING:  autovacuum worker started without a worker entry
[33mlocal_db   |[0m 2023-12-21 07:18:47.752 UTC [29] LOG:  checkpoint starting: time
[33mlocal_db   |[0m 2023-12-21 07:18:48.168 UTC [29] LOG:  checkpoint complete: wrote 4 buffers (0.0%); 0 WAL file(s) added, 0 removed, 0 recycled; write=0.316 s, sync=0.011 s, total=0.416 s; sync files=4, longest=0.009 s, average=0.003 s; distance=0 kB, estimate=0 kB; lsn=0/1941CF0, redo lsn=0/1941CB8
[33mlocal_db   |[0m 2023-12-21 09:03:48.345 UTC [29] LOG:  checkpoint starting: time
[33mlocal_db   |[0m 2023-12-21 09:03:48.691 UTC [29] LOG:  checkpoint complete: wrote 4 buffers (0.0%); 0 WAL file(s) added, 0 removed, 0 recycled; write=0.310 s, sync=0.011 s, total=0.347 s; sync files=4, longest=0.009 s, average=0.003 s; distance=0 kB, estimate=0 kB; lsn=0/1942088, redo lsn=0/1942050
[33mlocal_db   |[0m 2023-12-21 10:48:50.202 UTC [29] LOG:  checkpoint starting: time
[33mlocal_db   |[0m 2023-12-21 10:48:50.605 UTC [29] LOG:  checkpoint complete: wrote 4 buffers (0.0%); 0 WAL file(s) added, 0 removed, 0 recycled; write=0.312 s, sync=0.011 s, total=0.403 s; sync files=4, longest=0.008 s, average=0.003 s; distance=0 kB, estimate=0 kB; lsn=0/1942458, redo lsn=0/1942420
[33mlocal_db   |[0m 2023-12-21 12:18:51.759 UTC [29] LOG:  checkpoint starting: time
[33mlocal_db   |[0m 2023-12-21 12:18:52.106 UTC [29] LOG:  checkpoint complete: wrote 4 buffers (0.0%); 0 WAL file(s) added, 0 removed, 0 recycled; write=0.312 s, sync=0.011 s, total=0.347 s; sync files=4, longest=0.009 s, average=0.003 s; distance=1 kB, estimate=1 kB; lsn=0/1942868, redo lsn=0/1942830
[33mlocal_db   |[0m 2023-12-21 13:18:51.987 UTC [29] LOG:  checkpoint starting: time
[33mlocal_db   |[0m 2023-12-21 13:18:52.331 UTC [29] LOG:  checkpoint complete: wrote 4 buffers (0.0%); 0 WAL file(s) added, 0 removed, 0 recycled; write=0.312 s, sync=0.010 s, total=0.345 s; sync files=4, longest=0.008 s, average=0.003 s; distance=1 kB, estimate=1 kB; lsn=0/1942CC8, redo lsn=0/1942C90
[33mlocal_db   |[0m 2023-12-21 15:03:52.848 UTC [29] LOG:  checkpoint starting: time
[33mlocal_db   |[0m 2023-12-21 15:03:53.191 UTC [29] LOG:  checkpoint complete: wrote 4 buffers (0.0%); 0 WAL file(s) added, 0 removed, 0 recycled; write=0.312 s, sync=0.009 s, total=0.344 s; sync files=4, longest=0.007 s, average=0.003 s; distance=1 kB, estimate=1 kB; lsn=0/1943168, redo lsn=0/1943130
[33mlocal_db   |[0m 2023-12-21 16:48:53.441 UTC [29] LOG:  checkpoint starting: time
[33mlocal_db   |[0m 2023-12-21 16:48:53.787 UTC [29] LOG:  checkpoint complete: wrote 4 buffers (0.0%); 0 WAL file(s) added, 0 removed, 0 recycled; write=0.311 s, sync=0.011 s, total=0.346 s; sync files=4, longest=0.009 s, average=0.003 s; distance=1 kB, estimate=1 kB; lsn=0/1943658, redo lsn=0/1943620
[33mlocal_db   |[0m 2023-12-21 18:18:54.955 UTC [29] LOG:  checkpoint starting: time
[33mlocal_db   |[0m 2023-12-21 18:18:55.299 UTC [29] LOG:  checkpoint complete: wrote 4 buffers (0.0%); 0 WAL file(s) added, 0 removed, 0 recycled; write=0.312 s, sync=0.011 s, total=0.344 s; sync files=4, longest=0.009 s, average=0.003 s; distance=1 kB, estimate=1 kB; lsn=0/1943B88, redo lsn=0/1943B50
[33mlocal_db   |[0m 2023-12-21 22:21:07.037 UTC [33] WARNING:  autovacuum worker took too long to start; canceled
[33mlocal_db   |[0m 2023-12-21 22:25:05.778 UTC [33] WARNING:  autovacuum worker took too long to start; canceled
[33mlocal_db   |[0m 2023-12-21 22:33:54.861 UTC [33] WARNING:  autovacuum worker took too long to start; canceled
[33mlocal_db   |[0m 2023-12-21 22:46:48.186 UTC [33] WARNING:  autovacuum worker took too long to start; canceled
[33mlocal_db   |[0m 
[33mlocal_db   |[0m PostgreSQL Database directory appears to contain a database; Skipping initialization
[33mlocal_db   |[0m 
[33mlocal_db   |[0m 2024-01-07 22:07:32.611 UTC [1] LOG:  starting PostgreSQL 16.1 (Debian 16.1-1.pgdg120+1) on aarch64-unknown-linux-gnu, compiled by gcc (Debian 12.2.0-14) 12.2.0, 64-bit
[33mlocal_db   |[0m 2024-01-07 22:07:32.683 UTC [1] LOG:  listening on IPv4 address "0.0.0.0", port 5432
[33mlocal_db   |[0m 2024-01-07 22:07:32.684 UTC [1] LOG:  listening on IPv6 address "::", port 5432
[33mlocal_db   |[0m 2024-01-07 22:07:32.763 UTC [1] LOG:  listening on Unix socket "/var/run/postgresql/.s.PGSQL.5432"
[33mlocal_db   |[0m 2024-01-07 22:07:32.807 UTC [30] LOG:  database system was interrupted; last known up at 2023-12-21 18:18:55 UTC
[33mlocal_db   |[0m 2024-01-07 22:07:32.978 UTC [30] LOG:  database system was not properly shut down; automatic recovery in progress
[33mlocal_db   |[0m 2024-01-07 22:07:33.004 UTC [30] LOG:  redo starts at 0/1943B50
[33mlocal_db   |[0m 2024-01-07 22:07:33.004 UTC [30] LOG:  invalid record length at 0/1943C38: expected at least 24, got 0
[33mlocal_db   |[0m 2024-01-07 22:07:33.004 UTC [30] LOG:  redo done at 0/1943C00 system usage: CPU: user: 0.00 s, system: 0.00 s, elapsed: 0.00 s
[33mlocal_db   |[0m 2024-01-07 22:07:33.022 UTC [28] LOG:  checkpoint starting: end-of-recovery immediate wait
[33mlocal_db   |[0m 2024-01-07 22:07:33.152 UTC [28] LOG:  checkpoint complete: wrote 3 buffers (0.0%); 0 WAL file(s) added, 0 removed, 0 recycled; write=0.014 s, sync=0.005 s, total=0.136 s; sync files=2, longest=0.003 s, average=0.003 s; distance=0 kB, estimate=0 kB; lsn=0/1943C38, redo lsn=0/1943C38
[33mlocal_db   |[0m 2024-01-07 22:07:33.303 UTC [1] LOG:  database system is ready to accept connections
[33mlocal_db   |[0m 2024-01-07 22:30:58.161 UTC [32] WARNING:  autovacuum worker took too long to start; canceled
[33mlocal_db   |[0m 2024-01-07 22:32:59.912 UTC [46] WARNING:  autovacuum worker started without a worker entry
[33mlocal_db   |[0m 
[33mlocal_db   |[0m PostgreSQL Database directory appears to contain a database; Skipping initialization
[33mlocal_db   |[0m 
[33mlocal_db   |[0m 2024-01-07 22:43:44.965 UTC [1] LOG:  starting PostgreSQL 16.1 (Debian 16.1-1.pgdg120+1) on aarch64-unknown-linux-gnu, compiled by gcc (Debian 12.2.0-14) 12.2.0, 64-bit
[33mlocal_db   |[0m 2024-01-07 22:43:44.975 UTC [1] LOG:  listening on IPv4 address "0.0.0.0", port 5432
[33mlocal_db   |[0m 2024-01-07 22:43:44.975 UTC [1] LOG:  listening on IPv6 address "::", port 5432
[33mlocal_db   |[0m 2024-01-07 22:43:44.997 UTC [1] LOG:  listening on Unix socket "/var/run/postgresql/.s.PGSQL.5432"
[33mlocal_db   |[0m 2024-01-07 22:43:45.046 UTC [30] LOG:  database system was interrupted; last known up at 2024-01-07 22:07:33 UTC
[33mlocal_db   |[0m 2024-01-07 22:43:45.184 UTC [30] LOG:  database system was not properly shut down; automatic recovery in progress
[33mlocal_db   |[0m 2024-01-07 22:43:45.211 UTC [30] LOG:  redo starts at 0/1943CB0
[33mlocal_db   |[0m 2024-01-07 22:43:45.211 UTC [30] LOG:  invalid record length at 0/1943CE8: expected at least 24, got 0
[33mlocal_db   |[0m 2024-01-07 22:43:45.211 UTC [30] LOG:  redo done at 0/1943CB0 system usage: CPU: user: 0.00 s, system: 0.00 s, elapsed: 0.00 s
[33mlocal_db   |[0m 2024-01-07 22:43:45.236 UTC [28] LOG:  checkpoint starting: end-of-recovery immediate wait
[33mlocal_db   |[0m 2024-01-07 22:43:45.324 UTC [28] LOG:  checkpoint complete: wrote 3 buffers (0.0%); 0 WAL file(s) added, 0 removed, 0 recycled; write=0.041 s, sync=0.005 s, total=0.100 s; sync files=2, longest=0.003 s, average=0.003 s; distance=0 kB, estimate=0 kB; lsn=0/1943CE8, redo lsn=0/1943CE8
[33mlocal_db   |[0m 2024-01-07 22:43:45.464 UTC [1] LOG:  database system is ready to accept connections
[33mlocal_db   |[0m 2024-01-07 22:44:39.654 UTC [1] LOG:  received fast shutdown request
[33mlocal_db   |[0m 2024-01-07 22:44:39.665 UTC [1] LOG:  aborting any active transactions
[33mlocal_db   |[0m 2024-01-07 22:44:39.682 UTC [1] LOG:  background worker "logical replication launcher" (PID 33) exited with exit code 1
[33mlocal_db   |[0m 2024-01-07 22:44:39.688 UTC [28] LOG:  shutting down
[33mlocal_db   |[0m 2024-01-07 22:44:39.696 UTC [28] LOG:  checkpoint starting: shutdown immediate
[33mlocal_db   |[0m 2024-01-07 22:44:39.726 UTC [28] LOG:  checkpoint complete: wrote 0 buffers (0.0%); 0 WAL file(s) added, 0 removed, 0 recycled; write=0.004 s, sync=0.001 s, total=0.038 s; sync files=0, longest=0.000 s, average=0.000 s; distance=0 kB, estimate=0 kB; lsn=0/1943D98, redo lsn=0/1943D98
[33mlocal_db   |[0m 2024-01-07 22:44:39.754 UTC [1] LOG:  database system is shut down
[33mlocal_db   |[0m 
[33mlocal_db   |[0m PostgreSQL Database directory appears to contain a database; Skipping initialization
[33mlocal_db   |[0m 
[33mlocal_db   |[0m 2024-01-07 22:46:35.353 UTC [1] LOG:  starting PostgreSQL 16.1 (Debian 16.1-1.pgdg120+1) on aarch64-unknown-linux-gnu, compiled by gcc (Debian 12.2.0-14) 12.2.0, 64-bit
[33mlocal_db   |[0m 2024-01-07 22:46:35.355 UTC [1] LOG:  listening on IPv4 address "0.0.0.0", port 5432
[33mlocal_db   |[0m 2024-01-07 22:46:35.355 UTC [1] LOG:  listening on IPv6 address "::", port 5432
[33mlocal_db   |[0m 2024-01-07 22:46:35.372 UTC [1] LOG:  listening on Unix socket "/var/run/postgresql/.s.PGSQL.5432"
[33mlocal_db   |[0m 2024-01-07 22:46:35.413 UTC [30] LOG:  database system was shut down at 2024-01-07 22:44:39 UTC
[33mlocal_db   |[0m 2024-01-07 22:46:35.550 UTC [1] LOG:  database system is ready to accept connections
[33mlocal_db   |[0m 2024-01-07 22:47:45.978 UTC [1] LOG:  received fast shutdown request
[33mlocal_db   |[0m 2024-01-07 22:47:45.987 UTC [1] LOG:  aborting any active transactions
[33mlocal_db   |[0m 2024-01-07 22:47:45.999 UTC [1] LOG:  background worker "logical replication launcher" (PID 33) exited with exit code 1
[33mlocal_db   |[0m 2024-01-07 22:47:46.009 UTC [28] LOG:  shutting down
[33mlocal_db   |[0m 2024-01-07 22:47:46.016 UTC [28] LOG:  checkpoint starting: shutdown immediate
[33mlocal_db   |[0m 2024-01-07 22:47:46.081 UTC [28] LOG:  checkpoint complete: wrote 4 buffers (0.0%); 0 WAL file(s) added, 0 removed, 0 recycled; write=0.024 s, sync=0.011 s, total=0.072 s; sync files=3, longest=0.007 s, average=0.004 s; distance=0 kB, estimate=0 kB; lsn=0/1943E48, redo lsn=0/1943E48
[33mlocal_db   |[0m 2024-01-07 22:47:46.135 UTC [1] LOG:  database system is shut down
[33mlocal_db   |[0m 
[33mlocal_db   |[0m PostgreSQL Database directory appears to contain a database; Skipping initialization
[33mlocal_db   |[0m 
[33mlocal_db   |[0m 2024-01-07 23:13:34.204 UTC [1] LOG:  starting PostgreSQL 16.1 (Debian 16.1-1.pgdg120+1) on aarch64-unknown-linux-gnu, compiled by gcc (Debian 12.2.0-14) 12.2.0, 64-bit
[33mlocal_db   |[0m 2024-01-07 23:13:34.207 UTC [1] LOG:  listening on IPv4 address "0.0.0.0", port 5432
[33mlocal_db   |[0m 2024-01-07 23:13:34.207 UTC [1] LOG:  listening on IPv6 address "::", port 5432
[33mlocal_db   |[0m 2024-01-07 23:13:34.228 UTC [1] LOG:  listening on Unix socket "/var/run/postgresql/.s.PGSQL.5432"
[33mlocal_db   |[0m 2024-01-07 23:13:34.267 UTC [30] LOG:  database system was shut down at 2024-01-07 22:47:46 UTC
[33mlocal_db   |[0m 2024-01-07 23:13:34.428 UTC [1] LOG:  database system is ready to accept connections
[33mlocal_db   |[0m 2024-01-07 23:18:34.286 UTC [28] LOG:  checkpoint starting: time
[33mlocal_db   |[0m 2024-01-07 23:18:34.673 UTC [28] LOG:  checkpoint complete: wrote 3 buffers (0.0%); 0 WAL file(s) added, 0 removed, 0 recycled; write=0.104 s, sync=0.058 s, total=0.388 s; sync files=2, longest=0.031 s, average=0.029 s; distance=0 kB, estimate=0 kB; lsn=0/1943F30, redo lsn=0/1943EF8
[33mlocal_db   |[0m 
[33mlocal_db   |[0m PostgreSQL Database directory appears to contain a database; Skipping initialization
[33mlocal_db   |[0m 
[33mlocal_db   |[0m 2024-01-09 13:02:19.274 UTC [1] LOG:  starting PostgreSQL 16.1 (Debian 16.1-1.pgdg120+1) on aarch64-unknown-linux-gnu, compiled by gcc (Debian 12.2.0-14) 12.2.0, 64-bit
[33mlocal_db   |[0m 2024-01-09 13:02:19.287 UTC [1] LOG:  listening on IPv4 address "0.0.0.0", port 5432
[33mlocal_db   |[0m 2024-01-09 13:02:19.287 UTC [1] LOG:  listening on IPv6 address "::", port 5432
[33mlocal_db   |[0m 2024-01-09 13:02:19.386 UTC [1] LOG:  listening on Unix socket "/var/run/postgresql/.s.PGSQL.5432"
[33mlocal_db   |[0m 2024-01-09 13:02:19.471 UTC [29] LOG:  database system was interrupted; last known up at 2024-01-07 23:18:34 UTC
[33mlocal_db   |[0m 2024-01-09 13:02:19.588 UTC [29] LOG:  database system was not properly shut down; automatic recovery in progress
[33mlocal_db   |[0m 2024-01-09 13:02:19.608 UTC [29] LOG:  redo starts at 0/1943EF8
[33mlocal_db   |[0m 2024-01-09 13:02:19.609 UTC [29] LOG:  invalid record length at 0/1943FE0: expected at least 24, got 0
[33mlocal_db   |[0m 2024-01-09 13:02:19.609 UTC [29] LOG:  redo done at 0/1943FA8 system usage: CPU: user: 0.00 s, system: 0.00 s, elapsed: 0.00 s
[33mlocal_db   |[0m 2024-01-09 13:02:19.632 UTC [27] LOG:  checkpoint starting: end-of-recovery immediate wait
[33mlocal_db   |[0m 2024-01-09 13:02:19.688 UTC [27] LOG:  checkpoint complete: wrote 3 buffers (0.0%); 0 WAL file(s) added, 0 removed, 0 recycled; write=0.015 s, sync=0.005 s, total=0.063 s; sync files=2, longest=0.003 s, average=0.003 s; distance=0 kB, estimate=0 kB; lsn=0/1943FE0, redo lsn=0/1943FE0
[33mlocal_db   |[0m 2024-01-09 13:02:19.835 UTC [1] LOG:  database system is ready to accept connections
[33mlocal_db   |[0m 2024-01-09 13:17:19.891 UTC [27] LOG:  checkpoint starting: time
[33mlocal_db   |[0m 2024-01-09 13:17:20.238 UTC [27] LOG:  checkpoint complete: wrote 4 buffers (0.0%); 0 WAL file(s) added, 0 removed, 0 recycled; write=0.313 s, sync=0.012 s, total=0.348 s; sync files=4, longest=0.010 s, average=0.003 s; distance=1 kB, estimate=1 kB; lsn=0/1944578, redo lsn=0/1944540
[33mlocal_db   |[0m 2024-01-09 14:05:38.052 UTC [1] LOG:  received fast shutdown request
[33mlocal_db   |[0m 2024-01-09 14:05:38.085 UTC [1] LOG:  aborting any active transactions
[33mlocal_db   |[0m 2024-01-09 14:05:38.111 UTC [1] LOG:  background worker "logical replication launcher" (PID 32) exited with exit code 1
[33mlocal_db   |[0m 2024-01-09 14:05:38.123 UTC [27] LOG:  shutting down
[33mlocal_db   |[0m 2024-01-09 14:05:38.130 UTC [27] LOG:  checkpoint starting: shutdown immediate
[33mlocal_db   |[0m 2024-01-09 14:05:38.227 UTC [27] LOG:  checkpoint complete: wrote 1 buffers (0.0%); 0 WAL file(s) added, 0 removed, 0 recycled; write=0.007 s, sync=0.006 s, total=0.104 s; sync files=1, longest=0.006 s, average=0.006 s; distance=0 kB, estimate=1 kB; lsn=0/1944628, redo lsn=0/1944628
[33mlocal_db   |[0m 2024-01-09 14:05:38.268 UTC [1] LOG:  database system is shut down
[33mlocal_db   |[0m 
[33mlocal_db   |[0m PostgreSQL Database directory appears to contain a database; Skipping initialization
[33mlocal_db   |[0m 
[33mlocal_db   |[0m 2024-01-09 14:05:52.045 UTC [1] LOG:  starting PostgreSQL 16.1 (Debian 16.1-1.pgdg120+1) on aarch64-unknown-linux-gnu, compiled by gcc (Debian 12.2.0-14) 12.2.0, 64-bit
[33mlocal_db   |[0m 2024-01-09 14:05:52.050 UTC [1] LOG:  listening on IPv4 address "0.0.0.0", port 5432
[33mlocal_db   |[0m 2024-01-09 14:05:52.050 UTC [1] LOG:  listening on IPv6 address "::", port 5432
[33mlocal_db   |[0m 2024-01-09 14:05:52.066 UTC [1] LOG:  listening on Unix socket "/var/run/postgresql/.s.PGSQL.5432"
[33mlocal_db   |[0m 2024-01-09 14:05:52.093 UTC [29] LOG:  database system was shut down at 2024-01-09 14:05:38 UTC
[33mlocal_db   |[0m 2024-01-09 14:05:52.135 UTC [1] LOG:  database system is ready to accept connections
[33mlocal_db   |[0m 2024-01-09 14:10:54.652 UTC [27] LOG:  checkpoint starting: time
[33mlocal_db   |[0m 2024-01-09 14:10:55.957 UTC [27] LOG:  checkpoint complete: wrote 3 buffers (0.0%); 0 WAL file(s) added, 0 removed, 0 recycled; write=0.054 s, sync=0.011 s, total=1.361 s; sync files=2, longest=0.007 s, average=0.006 s; distance=0 kB, estimate=0 kB; lsn=0/1944710, redo lsn=0/19446D8
[33mlocal_db   |[0m 2024-01-09 14:14:05.037 UTC [1] LOG:  received fast shutdown request
[33mlocal_db   |[0m 2024-01-09 14:14:05.092 UTC [1] LOG:  aborting any active transactions
[33mlocal_db   |[0m 2024-01-09 14:14:05.124 UTC [1] LOG:  background worker "logical replication launcher" (PID 32) exited with exit code 1
[33mlocal_db   |[0m 2024-01-09 14:14:05.129 UTC [27] LOG:  shutting down
[33mlocal_db   |[0m 2024-01-09 14:14:05.140 UTC [27] LOG:  checkpoint starting: shutdown immediate
[33mlocal_db   |[0m 2024-01-09 14:14:05.225 UTC [27] LOG:  checkpoint complete: wrote 0 buffers (0.0%); 0 WAL file(s) added, 0 removed, 0 recycled; write=0.007 s, sync=0.001 s, total=0.096 s; sync files=0, longest=0.000 s, average=0.000 s; distance=0 kB, estimate=0 kB; lsn=0/19447C0, redo lsn=0/19447C0
[33mlocal_db   |[0m 2024-01-09 14:14:05.284 UTC [1] LOG:  database system is shut down
[33mlocal_db   |[0m 
[33mlocal_db   |[0m PostgreSQL Database directory appears to contain a database; Skipping initialization
[33mlocal_db   |[0m 
[33mlocal_db   |[0m 2024-01-09 14:14:29.987 UTC [1] LOG:  starting PostgreSQL 16.1 (Debian 16.1-1.pgdg120+1) on aarch64-unknown-linux-gnu, compiled by gcc (Debian 12.2.0-14) 12.2.0, 64-bit
[33mlocal_db   |[0m 2024-01-09 14:14:30.000 UTC [1] LOG:  listening on IPv4 address "0.0.0.0", port 5432
[33mlocal_db   |[0m 2024-01-09 14:14:30.000 UTC [1] LOG:  listening on IPv6 address "::", port 5432
[33mlocal_db   |[0m 2024-01-09 14:14:30.071 UTC [1] LOG:  listening on Unix socket "/var/run/postgresql/.s.PGSQL.5432"
[33mlocal_db   |[0m 2024-01-09 14:14:30.153 UTC [30] LOG:  database system was shut down at 2024-01-09 14:14:05 UTC
[33mlocal_db   |[0m 2024-01-09 14:14:30.366 UTC [1] LOG:  database system is ready to accept connections
[33mlocal_db   |[0m 2024-01-09 14:16:05.082 UTC [1] LOG:  received fast shutdown request
[33mlocal_db   |[0m 2024-01-09 14:16:05.094 UTC [1] LOG:  aborting any active transactions
[33mlocal_db   |[0m 2024-01-09 14:16:05.111 UTC [1] LOG:  background worker "logical replication launcher" (PID 33) exited with exit code 1
[33mlocal_db   |[0m 2024-01-09 14:16:05.111 UTC [28] LOG:  shutting down
[33mlocal_db   |[0m 2024-01-09 14:16:05.118 UTC [28] LOG:  checkpoint starting: shutdown immediate
[33mlocal_db   |[0m 2024-01-09 14:16:05.234 UTC [28] LOG:  checkpoint complete: wrote 3 buffers (0.0%); 0 WAL file(s) added, 0 removed, 0 recycled; write=0.011 s, sync=0.004 s, total=0.123 s; sync files=2, longest=0.002 s, average=0.002 s; distance=0 kB, estimate=0 kB; lsn=0/1944870, redo lsn=0/1944870
[33mlocal_db   |[0m 2024-01-09 14:16:05.260 UTC [1] LOG:  database system is shut down
[33mlocal_db   |[0m 
[33mlocal_db   |[0m PostgreSQL Database directory appears to contain a database; Skipping initialization
[33mlocal_db   |[0m 
[33mlocal_db   |[0m 2024-01-09 14:20:20.999 UTC [1] LOG:  starting PostgreSQL 16.1 (Debian 16.1-1.pgdg120+1) on aarch64-unknown-linux-gnu, compiled by gcc (Debian 12.2.0-14) 12.2.0, 64-bit
[33mlocal_db   |[0m 2024-01-09 14:20:21.002 UTC [1] LOG:  listening on IPv4 address "0.0.0.0", port 5432
[33mlocal_db   |[0m 2024-01-09 14:20:21.003 UTC [1] LOG:  listening on IPv6 address "::", port 5432
[33mlocal_db   |[0m 2024-01-09 14:20:21.028 UTC [1] LOG:  listening on Unix socket "/var/run/postgresql/.s.PGSQL.5432"
[33mlocal_db   |[0m 2024-01-09 14:20:21.068 UTC [30] LOG:  database system was shut down at 2024-01-09 14:16:05 UTC
[33mlocal_db   |[0m 2024-01-09 14:20:21.107 UTC [1] LOG:  database system is ready to accept connections
[33mlocal_db   |[0m 2024-01-09 14:25:21.086 UTC [28] LOG:  checkpoint starting: time
[33mlocal_db   |[0m 2024-01-09 14:25:21.181 UTC [28] LOG:  checkpoint complete: wrote 3 buffers (0.0%); 0 WAL file(s) added, 0 removed, 0 recycled; write=0.027 s, sync=0.004 s, total=0.098 s; sync files=2, longest=0.002 s, average=0.002 s; distance=0 kB, estimate=0 kB; lsn=0/1944958, redo lsn=0/1944920
[33mlocal_db   |[0m 2024-01-09 14:55:20.234 UTC [1] LOG:  received fast shutdown request
[33mlocal_db   |[0m 2024-01-09 14:55:20.260 UTC [1] LOG:  aborting any active transactions
[33mlocal_db   |[0m 2024-01-09 14:55:20.274 UTC [1] LOG:  background worker "logical replication launcher" (PID 33) exited with exit code 1
[33mlocal_db   |[0m 2024-01-09 14:55:20.290 UTC [28] LOG:  shutting down
[33mlocal_db   |[0m 2024-01-09 14:55:20.306 UTC [28] LOG:  checkpoint starting: shutdown immediate
[33mlocal_db   |[0m 2024-01-09 14:55:20.364 UTC [28] LOG:  checkpoint complete: wrote 0 buffers (0.0%); 0 WAL file(s) added, 0 removed, 0 recycled; write=0.004 s, sync=0.001 s, total=0.075 s; sync files=0, longest=0.000 s, average=0.000 s; distance=0 kB, estimate=0 kB; lsn=0/1944A08, redo lsn=0/1944A08
[33mlocal_db   |[0m 2024-01-09 14:55:20.424 UTC [1] LOG:  database system is shut down
[33mlocal_db   |[0m 
[33mlocal_db   |[0m PostgreSQL Database directory appears to contain a database; Skipping initialization
[33mlocal_db   |[0m 
[33mlocal_db   |[0m 2024-01-09 14:55:46.778 UTC [1] LOG:  starting PostgreSQL 16.1 (Debian 16.1-1.pgdg120+1) on aarch64-unknown-linux-gnu, compiled by gcc (Debian 12.2.0-14) 12.2.0, 64-bit
[33mlocal_db   |[0m 2024-01-09 14:55:46.782 UTC [1] LOG:  listening on IPv4 address "0.0.0.0", port 5432
[33mlocal_db   |[0m 2024-01-09 14:55:46.782 UTC [1] LOG:  listening on IPv6 address "::", port 5432
[33mlocal_db   |[0m 2024-01-09 14:55:46.795 UTC [1] LOG:  listening on Unix socket "/var/run/postgresql/.s.PGSQL.5432"
[33mlocal_db   |[0m 2024-01-09 14:55:46.820 UTC [30] LOG:  database system was shut down at 2024-01-09 14:55:20 UTC
[33mlocal_db   |[0m 2024-01-09 14:55:46.855 UTC [1] LOG:  database system is ready to accept connections
[33mlocal_db   |[0m 2024-01-09 15:00:46.893 UTC [28] LOG:  checkpoint starting: time
[33mlocal_db   |[0m 2024-01-09 15:00:46.944 UTC [28] LOG:  checkpoint complete: wrote 3 buffers (0.0%); 0 WAL file(s) added, 0 removed, 0 recycled; write=0.017 s, sync=0.005 s, total=0.051 s; sync files=2, longest=0.003 s, average=0.003 s; distance=0 kB, estimate=0 kB; lsn=0/1944AF0, redo lsn=0/1944AB8
[33mlocal_db   |[0m 2024-01-09 16:25:47.883 UTC [28] LOG:  checkpoint starting: time
[33mlocal_db   |[0m 2024-01-09 16:25:48.230 UTC [28] LOG:  checkpoint complete: wrote 4 buffers (0.0%); 0 WAL file(s) added, 0 removed, 0 recycled; write=0.313 s, sync=0.011 s, total=0.348 s; sync files=4, longest=0.009 s, average=0.003 s; distance=1 kB, estimate=1 kB; lsn=0/19450B0, redo lsn=0/1945078
[33mlocal_db   |[0m 2024-01-09 16:30:47.300 UTC [28] LOG:  checkpoint starting: time
[33mlocal_db   |[0m 2024-01-09 16:30:47.640 UTC [28] LOG:  checkpoint complete: wrote 4 buffers (0.0%); 0 WAL file(s) added, 0 removed, 0 recycled; write=0.308 s, sync=0.009 s, total=0.341 s; sync files=4, longest=0.007 s, average=0.003 s; distance=1 kB, estimate=1 kB; lsn=0/19456C0, redo lsn=0/1945688
[33mlocal_db   |[0m 2024-01-09 16:36:01.346 UTC [1] LOG:  received fast shutdown request
[33mlocal_db   |[0m 2024-01-09 16:36:01.354 UTC [1] LOG:  aborting any active transactions
[33mlocal_db   |[0m 2024-01-09 16:36:01.369 UTC [1] LOG:  background worker "logical replication launcher" (PID 33) exited with exit code 1
[33mlocal_db   |[0m 2024-01-09 16:36:01.384 UTC [28] LOG:  shutting down
[33mlocal_db   |[0m 2024-01-09 16:36:01.393 UTC [28] LOG:  checkpoint starting: shutdown immediate
[33mlocal_db   |[0m 2024-01-09 16:36:01.429 UTC [28] LOG:  checkpoint complete: wrote 0 buffers (0.0%); 0 WAL file(s) added, 0 removed, 0 recycled; write=0.005 s, sync=0.001 s, total=0.046 s; sync files=0, longest=0.000 s, average=0.000 s; distance=0 kB, estimate=1 kB; lsn=0/1945770, redo lsn=0/1945770
[33mlocal_db   |[0m 2024-01-09 16:36:01.460 UTC [1] LOG:  database system is shut down
[33mlocal_db   |[0m 
[33mlocal_db   |[0m PostgreSQL Database directory appears to contain a database; Skipping initialization
[33mlocal_db   |[0m 
[33mlocal_db   |[0m 2024-01-09 16:36:11.428 UTC [1] LOG:  starting PostgreSQL 16.1 (Debian 16.1-1.pgdg120+1) on aarch64-unknown-linux-gnu, compiled by gcc (Debian 12.2.0-14) 12.2.0, 64-bit
[33mlocal_db   |[0m 2024-01-09 16:36:11.428 UTC [1] LOG:  listening on IPv4 address "0.0.0.0", port 5432
[33mlocal_db   |[0m 2024-01-09 16:36:11.428 UTC [1] LOG:  listening on IPv6 address "::", port 5432
[33mlocal_db   |[0m 2024-01-09 16:36:11.497 UTC [1] LOG:  listening on Unix socket "/var/run/postgresql/.s.PGSQL.5432"
[33mlocal_db   |[0m 2024-01-09 16:36:11.522 UTC [30] LOG:  database system was shut down at 2024-01-09 16:36:01 UTC
[33mlocal_db   |[0m 2024-01-09 16:36:11.555 UTC [1] LOG:  database system is ready to accept connections
[33mlocal_db   |[0m 2024-01-09 16:41:11.619 UTC [28] LOG:  checkpoint starting: time
[33mlocal_db   |[0m 2024-01-09 16:41:11.663 UTC [28] LOG:  checkpoint complete: wrote 3 buffers (0.0%); 0 WAL file(s) added, 0 removed, 0 recycled; write=0.012 s, sync=0.004 s, total=0.044 s; sync files=2, longest=0.002 s, average=0.002 s; distance=0 kB, estimate=0 kB; lsn=0/1945858, redo lsn=0/1945820
[33mlocal_db   |[0m 2024-01-09 16:44:13.689 UTC [1] LOG:  received fast shutdown request
[33mlocal_db   |[0m 2024-01-09 16:44:13.697 UTC [1] LOG:  aborting any active transactions
[33mlocal_db   |[0m 2024-01-09 16:44:13.720 UTC [1] LOG:  background worker "logical replication launcher" (PID 33) exited with exit code 1
[33mlocal_db   |[0m 2024-01-09 16:44:13.721 UTC [28] LOG:  shutting down
[33mlocal_db   |[0m 2024-01-09 16:44:13.727 UTC [28] LOG:  checkpoint starting: shutdown immediate
[33mlocal_db   |[0m 2024-01-09 16:44:13.752 UTC [28] LOG:  checkpoint complete: wrote 0 buffers (0.0%); 0 WAL file(s) added, 0 removed, 0 recycled; write=0.004 s, sync=0.001 s, total=0.032 s; sync files=0, longest=0.000 s, average=0.000 s; distance=0 kB, estimate=0 kB; lsn=0/1945908, redo lsn=0/1945908
[33mlocal_db   |[0m 2024-01-09 16:44:13.778 UTC [1] LOG:  database system is shut down
[33mlocal_db   |[0m 
[33mlocal_db   |[0m PostgreSQL Database directory appears to contain a database; Skipping initialization
[33mlocal_db   |[0m 
[33mlocal_db   |[0m 2024-01-09 16:44:22.757 UTC [1] LOG:  starting PostgreSQL 16.1 (Debian 16.1-1.pgdg120+1) on aarch64-unknown-linux-gnu, compiled by gcc (Debian 12.2.0-14) 12.2.0, 64-bit
[33mlocal_db   |[0m 2024-01-09 16:44:22.758 UTC [1] LOG:  listening on IPv4 address "0.0.0.0", port 5432
[33mlocal_db   |[0m 2024-01-09 16:44:22.758 UTC [1] LOG:  listening on IPv6 address "::", port 5432
[33mlocal_db   |[0m 2024-01-09 16:44:22.774 UTC [1] LOG:  listening on Unix socket "/var/run/postgresql/.s.PGSQL.5432"
[33mlocal_db   |[0m 2024-01-09 16:44:22.801 UTC [30] LOG:  database system was shut down at 2024-01-09 16:44:13 UTC
[33mlocal_db   |[0m 2024-01-09 16:44:22.842 UTC [1] LOG:  database system is ready to accept connections
[33mlocal_db   |[0m 2024-01-09 16:47:57.465 UTC [1] LOG:  received fast shutdown request
[33mlocal_db   |[0m 2024-01-09 16:47:57.474 UTC [1] LOG:  aborting any active transactions
[33mlocal_db   |[0m 2024-01-09 16:47:57.489 UTC [1] LOG:  background worker "logical replication launcher" (PID 33) exited with exit code 1
[33mlocal_db   |[0m 2024-01-09 16:47:57.498 UTC [28] LOG:  shutting down
[33mlocal_db   |[0m 2024-01-09 16:47:57.505 UTC [28] LOG:  checkpoint starting: shutdown immediate
[33mlocal_db   |[0m 2024-01-09 16:47:57.542 UTC [28] LOG:  checkpoint complete: wrote 4 buffers (0.0%); 0 WAL file(s) added, 0 removed, 0 recycled; write=0.012 s, sync=0.007 s, total=0.044 s; sync files=3, longest=0.004 s, average=0.003 s; distance=0 kB, estimate=0 kB; lsn=0/19459B8, redo lsn=0/19459B8
[33mlocal_db   |[0m 2024-01-09 16:47:57.568 UTC [1] LOG:  database system is shut down
[33mlocal_db   |[0m 
[33mlocal_db   |[0m PostgreSQL Database directory appears to contain a database; Skipping initialization
[33mlocal_db   |[0m 
[33mlocal_db   |[0m 2024-01-09 16:53:49.847 UTC [1] LOG:  starting PostgreSQL 16.1 (Debian 16.1-1.pgdg120+1) on aarch64-unknown-linux-gnu, compiled by gcc (Debian 12.2.0-14) 12.2.0, 64-bit
[33mlocal_db   |[0m 2024-01-09 16:53:49.848 UTC [1] LOG:  listening on IPv4 address "0.0.0.0", port 5432
[33mlocal_db   |[0m 2024-01-09 16:53:49.848 UTC [1] LOG:  listening on IPv6 address "::", port 5432
[33mlocal_db   |[0m 2024-01-09 16:53:49.869 UTC [1] LOG:  listening on Unix socket "/var/run/postgresql/.s.PGSQL.5432"
[33mlocal_db   |[0m 2024-01-09 16:53:49.899 UTC [30] LOG:  database system was shut down at 2024-01-09 16:47:57 UTC
[33mlocal_db   |[0m 2024-01-09 16:53:49.961 UTC [1] LOG:  database system is ready to accept connections
[33mlocal_db   |[0m 
[33mlocal_db   |[0m PostgreSQL Database directory appears to contain a database; Skipping initialization
[33mlocal_db   |[0m 
[33mlocal_db   |[0m 2024-01-09 16:54:14.706 UTC [1] LOG:  starting PostgreSQL 16.1 (Debian 16.1-1.pgdg120+1) on aarch64-unknown-linux-gnu, compiled by gcc (Debian 12.2.0-14) 12.2.0, 64-bit
[33mlocal_db   |[0m 2024-01-09 16:54:14.708 UTC [1] LOG:  listening on IPv4 address "0.0.0.0", port 5432
[33mlocal_db   |[0m 2024-01-09 16:54:14.708 UTC [1] LOG:  listening on IPv6 address "::", port 5432
[33mlocal_db   |[0m 2024-01-09 16:54:14.724 UTC [1] LOG:  listening on Unix socket "/var/run/postgresql/.s.PGSQL.5432"
[33mlocal_db   |[0m 2024-01-09 16:54:14.749 UTC [28] LOG:  database system was interrupted; last known up at 2024-01-09 16:53:49 UTC
[33mlocal_db   |[0m 2024-01-09 16:54:14.864 UTC [28] LOG:  database system was not properly shut down; automatic recovery in progress
[33mlocal_db   |[0m 2024-01-09 16:54:14.874 UTC [28] LOG:  invalid record length at 0/1945A30: expected at least 24, got 0
[33mlocal_db   |[0m 2024-01-09 16:54:14.874 UTC [28] LOG:  redo is not required
[33mlocal_db   |[0m 2024-01-09 16:54:14.890 UTC [26] LOG:  checkpoint starting: end-of-recovery immediate wait
[33mlocal_db   |[0m 2024-01-09 16:54:14.926 UTC [26] LOG:  checkpoint complete: wrote 3 buffers (0.0%); 0 WAL file(s) added, 0 removed, 0 recycled; write=0.012 s, sync=0.004 s, total=0.042 s; sync files=2, longest=0.003 s, average=0.002 s; distance=0 kB, estimate=0 kB; lsn=0/1945A30, redo lsn=0/1945A30
[33mlocal_db   |[0m 2024-01-09 16:54:14.950 UTC [1] LOG:  database system is ready to accept connections
[33mlocal_db   |[0m 2024-01-09 17:19:15.271 UTC [26] LOG:  checkpoint starting: time
[33mlocal_db   |[0m 2024-01-09 17:19:15.639 UTC [26] LOG:  checkpoint complete: wrote 4 buffers (0.0%); 0 WAL file(s) added, 0 removed, 0 recycled; write=0.323 s, sync=0.009 s, total=0.368 s; sync files=4, longest=0.008 s, average=0.003 s; distance=1 kB, estimate=1 kB; lsn=0/1946098, redo lsn=0/1946060
[33mlocal_db   |[0m 2024-01-09 17:35:39.757 UTC [30] WARNING:  autovacuum worker took too long to start; canceled
[33mlocal_db   |[0m 2024-01-09 17:38:28.176 UTC [56] WARNING:  autovacuum worker started without a worker entry
[33mlocal_db   |[0m 
[33mlocal_db   |[0m PostgreSQL Database directory appears to contain a database; Skipping initialization
[33mlocal_db   |[0m 
[33mlocal_db   |[0m 2024-01-09 18:02:28.113 UTC [1] LOG:  starting PostgreSQL 16.1 (Debian 16.1-1.pgdg120+1) on aarch64-unknown-linux-gnu, compiled by gcc (Debian 12.2.0-14) 12.2.0, 64-bit
[33mlocal_db   |[0m 2024-01-09 18:02:28.115 UTC [1] LOG:  listening on IPv4 address "0.0.0.0", port 5432
[33mlocal_db   |[0m 2024-01-09 18:02:28.115 UTC [1] LOG:  listening on IPv6 address "::", port 5432
[33mlocal_db   |[0m 2024-01-09 18:02:28.151 UTC [1] LOG:  listening on Unix socket "/var/run/postgresql/.s.PGSQL.5432"
[33mlocal_db   |[0m 2024-01-09 18:02:28.186 UTC [29] LOG:  database system was interrupted; last known up at 2024-01-09 17:19:15 UTC
[33mlocal_db   |[0m 2024-01-09 18:02:28.414 UTC [29] LOG:  database system was not properly shut down; automatic recovery in progress
[33mlocal_db   |[0m 2024-01-09 18:02:28.445 UTC [29] LOG:  redo starts at 0/1946060
[33mlocal_db   |[0m 2024-01-09 18:02:28.445 UTC [29] LOG:  invalid record length at 0/1946148: expected at least 24, got 0
[33mlocal_db   |[0m 2024-01-09 18:02:28.445 UTC [29] LOG:  redo done at 0/1946110 system usage: CPU: user: 0.00 s, system: 0.00 s, elapsed: 0.00 s
[33mlocal_db   |[0m 2024-01-09 18:02:28.471 UTC [27] LOG:  checkpoint starting: end-of-recovery immediate wait
[33mlocal_db   |[0m 2024-01-09 18:02:28.546 UTC [27] LOG:  checkpoint complete: wrote 3 buffers (0.0%); 0 WAL file(s) added, 0 removed, 0 recycled; write=0.019 s, sync=0.005 s, total=0.081 s; sync files=2, longest=0.003 s, average=0.003 s; distance=0 kB, estimate=0 kB; lsn=0/1946148, redo lsn=0/1946148
[33mlocal_db   |[0m 2024-01-09 18:02:28.677 UTC [1] LOG:  database system is ready to accept connections
[33mlocal_db   |[0m 2024-01-09 20:06:36.691 UTC [1] LOG:  received fast shutdown request
[33mlocal_db   |[0m 2024-01-09 20:06:36.699 UTC [1] LOG:  aborting any active transactions
[33mlocal_db   |[0m 2024-01-09 20:06:36.713 UTC [1] LOG:  background worker "logical replication launcher" (PID 32) exited with exit code 1
[33mlocal_db   |[0m 2024-01-09 20:06:36.722 UTC [27] LOG:  shutting down
[33mlocal_db   |[0m 2024-01-09 20:06:36.728 UTC [27] LOG:  checkpoint starting: shutdown immediate
[33mlocal_db   |[0m 2024-01-09 20:06:36.753 UTC [27] LOG:  checkpoint complete: wrote 0 buffers (0.0%); 0 WAL file(s) added, 0 removed, 0 recycled; write=0.005 s, sync=0.001 s, total=0.031 s; sync files=0, longest=0.000 s, average=0.000 s; distance=0 kB, estimate=0 kB; lsn=0/19461F8, redo lsn=0/19461F8
[33mlocal_db   |[0m 2024-01-09 20:06:36.779 UTC [1] LOG:  database system is shut down
[33mlocal_db   |[0m 
[33mlocal_db   |[0m PostgreSQL Database directory appears to contain a database; Skipping initialization
[33mlocal_db   |[0m 
[33mlocal_db   |[0m 2024-01-09 20:11:32.104 UTC [1] LOG:  starting PostgreSQL 16.1 (Debian 16.1-1.pgdg120+1) on aarch64-unknown-linux-gnu, compiled by gcc (Debian 12.2.0-14) 12.2.0, 64-bit
[33mlocal_db   |[0m 2024-01-09 20:11:32.106 UTC [1] LOG:  listening on IPv4 address "0.0.0.0", port 5432
[33mlocal_db   |[0m 2024-01-09 20:11:32.107 UTC [1] LOG:  listening on IPv6 address "::", port 5432
[33mlocal_db   |[0m 2024-01-09 20:11:32.303 UTC [1] LOG:  listening on Unix socket "/var/run/postgresql/.s.PGSQL.5432"
[33mlocal_db   |[0m 2024-01-09 20:11:32.338 UTC [30] LOG:  database system was shut down at 2024-01-09 20:06:36 UTC
[33mlocal_db   |[0m 2024-01-09 20:11:32.380 UTC [1] LOG:  database system is ready to accept connections
[33mlocal_db   |[0m 2024-01-09 20:12:56.703 UTC [1] LOG:  received fast shutdown request
[33mlocal_db   |[0m 2024-01-09 20:12:56.711 UTC [1] LOG:  aborting any active transactions
[33mlocal_db   |[0m 2024-01-09 20:12:56.727 UTC [1] LOG:  background worker "logical replication launcher" (PID 33) exited with exit code 1
[33mlocal_db   |[0m 2024-01-09 20:12:56.728 UTC [28] LOG:  shutting down
[33mlocal_db   |[0m 2024-01-09 20:12:56.733 UTC [28] LOG:  checkpoint starting: shutdown immediate
[33mlocal_db   |[0m 2024-01-09 20:12:56.769 UTC [28] LOG:  checkpoint complete: wrote 3 buffers (0.0%); 0 WAL file(s) added, 0 removed, 0 recycled; write=0.011 s, sync=0.004 s, total=0.042 s; sync files=2, longest=0.002 s, average=0.002 s; distance=0 kB, estimate=0 kB; lsn=0/19462A8, redo lsn=0/19462A8
[33mlocal_db   |[0m 2024-01-09 20:12:56.794 UTC [1] LOG:  database system is shut down
[33mlocal_db   |[0m 
[33mlocal_db   |[0m PostgreSQL Database directory appears to contain a database; Skipping initialization
[33mlocal_db   |[0m 
[33mlocal_db   |[0m 2024-01-09 20:16:25.499 UTC [1] LOG:  starting PostgreSQL 16.1 (Debian 16.1-1.pgdg120+1) on aarch64-unknown-linux-gnu, compiled by gcc (Debian 12.2.0-14) 12.2.0, 64-bit
[33mlocal_db   |[0m 2024-01-09 20:16:25.501 UTC [1] LOG:  listening on IPv4 address "0.0.0.0", port 5432
[33mlocal_db   |[0m 2024-01-09 20:16:25.501 UTC [1] LOG:  listening on IPv6 address "::", port 5432
[33mlocal_db   |[0m 2024-01-09 20:16:25.613 UTC [1] LOG:  listening on Unix socket "/var/run/postgresql/.s.PGSQL.5432"
[33mlocal_db   |[0m 2024-01-09 20:16:25.641 UTC [29] LOG:  database system was shut down at 2024-01-09 20:12:56 UTC
[33mlocal_db   |[0m 2024-01-09 20:16:25.726 UTC [1] LOG:  database system is ready to accept connections
[33mlocal_db   |[0m 2024-01-09 20:21:25.685 UTC [27] LOG:  checkpoint starting: time
[33mlocal_db   |[0m 2024-01-09 20:21:25.733 UTC [27] LOG:  checkpoint complete: wrote 3 buffers (0.0%); 0 WAL file(s) added, 0 removed, 0 recycled; write=0.015 s, sync=0.004 s, total=0.049 s; sync files=2, longest=0.002 s, average=0.002 s; distance=0 kB, estimate=0 kB; lsn=0/1946390, redo lsn=0/1946358
[33mlocal_db   |[0m 2024-01-09 20:29:26.842 UTC [1] LOG:  received fast shutdown request
[33mlocal_db   |[0m 2024-01-09 20:29:26.851 UTC [1] LOG:  aborting any active transactions
[33mlocal_db   |[0m 2024-01-09 20:29:26.864 UTC [1] LOG:  background worker "logical replication launcher" (PID 32) exited with exit code 1
[33mlocal_db   |[0m 2024-01-09 20:29:26.868 UTC [27] LOG:  shutting down
[33mlocal_db   |[0m 2024-01-09 20:29:26.874 UTC [27] LOG:  checkpoint starting: shutdown immediate
[33mlocal_db   |[0m 2024-01-09 20:29:26.900 UTC [27] LOG:  checkpoint complete: wrote 0 buffers (0.0%); 0 WAL file(s) added, 0 removed, 0 recycled; write=0.004 s, sync=0.001 s, total=0.032 s; sync files=0, longest=0.000 s, average=0.000 s; distance=0 kB, estimate=0 kB; lsn=0/1946440, redo lsn=0/1946440
[33mlocal_db   |[0m 2024-01-09 20:29:26.925 UTC [1] LOG:  database system is shut down
[33mlocal_db   |[0m 
[33mlocal_db   |[0m PostgreSQL Database directory appears to contain a database; Skipping initialization
[33mlocal_db   |[0m 
[33mlocal_db   |[0m 2024-01-09 20:33:39.351 UTC [1] LOG:  starting PostgreSQL 16.1 (Debian 16.1-1.pgdg120+1) on aarch64-unknown-linux-gnu, compiled by gcc (Debian 12.2.0-14) 12.2.0, 64-bit
[33mlocal_db   |[0m 2024-01-09 20:33:39.352 UTC [1] LOG:  listening on IPv4 address "0.0.0.0", port 5432
[33mlocal_db   |[0m 2024-01-09 20:33:39.352 UTC [1] LOG:  listening on IPv6 address "::", port 5432
[33mlocal_db   |[0m 2024-01-09 20:33:39.633 UTC [1] LOG:  listening on Unix socket "/var/run/postgresql/.s.PGSQL.5432"
[33mlocal_db   |[0m 2024-01-09 20:33:39.664 UTC [29] LOG:  database system was shut down at 2024-01-09 20:29:26 UTC
[33mlocal_db   |[0m 2024-01-09 20:33:39.719 UTC [1] LOG:  database system is ready to accept connections
[33mlocal_db   |[0m 2024-01-09 20:36:52.113 UTC [1] LOG:  received fast shutdown request
[33mlocal_db   |[0m 2024-01-09 20:36:52.121 UTC [1] LOG:  aborting any active transactions
[33mlocal_db   |[0m 2024-01-09 20:36:52.133 UTC [1] LOG:  background worker "logical replication launcher" (PID 32) exited with exit code 1
[33mlocal_db   |[0m 2024-01-09 20:36:52.139 UTC [27] LOG:  shutting down
[33mlocal_db   |[0m 2024-01-09 20:36:52.144 UTC [27] LOG:  checkpoint starting: shutdown immediate
[33mlocal_db   |[0m 2024-01-09 20:36:52.178 UTC [27] LOG:  checkpoint complete: wrote 3 buffers (0.0%); 0 WAL file(s) added, 0 removed, 0 recycled; write=0.010 s, sync=0.003 s, total=0.039 s; sync files=2, longest=0.002 s, average=0.002 s; distance=0 kB, estimate=0 kB; lsn=0/19464F0, redo lsn=0/19464F0
[33mlocal_db   |[0m 2024-01-09 20:36:52.202 UTC [1] LOG:  database system is shut down
[33mlocal_db   |[0m 
[33mlocal_db   |[0m PostgreSQL Database directory appears to contain a database; Skipping initialization
[33mlocal_db   |[0m 
[33mlocal_db   |[0m 2024-01-09 20:40:06.151 UTC [1] LOG:  starting PostgreSQL 16.1 (Debian 16.1-1.pgdg120+1) on aarch64-unknown-linux-gnu, compiled by gcc (Debian 12.2.0-14) 12.2.0, 64-bit
[33mlocal_db   |[0m 2024-01-09 20:40:06.152 UTC [1] LOG:  listening on IPv4 address "0.0.0.0", port 5432
[33mlocal_db   |[0m 2024-01-09 20:40:06.152 UTC [1] LOG:  listening on IPv6 address "::", port 5432
[33mlocal_db   |[0m 2024-01-09 20:40:06.206 UTC [1] LOG:  listening on Unix socket "/var/run/postgresql/.s.PGSQL.5432"
[33mlocal_db   |[0m 2024-01-09 20:40:06.233 UTC [29] LOG:  database system was shut down at 2024-01-09 20:36:52 UTC
[33mlocal_db   |[0m 2024-01-09 20:40:06.265 UTC [1] LOG:  database system is ready to accept connections
[33mlocal_db   |[0m 2024-01-09 20:45:06.254 UTC [27] LOG:  checkpoint starting: time
[33mlocal_db   |[0m 2024-01-09 20:45:06.302 UTC [27] LOG:  checkpoint complete: wrote 3 buffers (0.0%); 0 WAL file(s) added, 0 removed, 0 recycled; write=0.017 s, sync=0.004 s, total=0.049 s; sync files=2, longest=0.003 s, average=0.002 s; distance=0 kB, estimate=0 kB; lsn=0/19465D8, redo lsn=0/19465A0
[33mlocal_db   |[0m 2024-01-09 20:46:15.187 UTC [1] LOG:  received fast shutdown request
[33mlocal_db   |[0m 2024-01-09 20:46:15.196 UTC [1] LOG:  aborting any active transactions
[33mlocal_db   |[0m 2024-01-09 20:46:15.210 UTC [1] LOG:  background worker "logical replication launcher" (PID 32) exited with exit code 1
[33mlocal_db   |[0m 2024-01-09 20:46:15.219 UTC [27] LOG:  shutting down
[33mlocal_db   |[0m 2024-01-09 20:46:15.279 UTC [27] LOG:  checkpoint starting: shutdown immediate
[33mlocal_db   |[0m 2024-01-09 20:46:15.306 UTC [27] LOG:  checkpoint complete: wrote 0 buffers (0.0%); 0 WAL file(s) added, 0 removed, 0 recycled; write=0.004 s, sync=0.001 s, total=0.087 s; sync files=0, longest=0.000 s, average=0.000 s; distance=0 kB, estimate=0 kB; lsn=0/1946688, redo lsn=0/1946688
[33mlocal_db   |[0m 2024-01-09 20:46:15.331 UTC [1] LOG:  database system is shut down
[33mlocal_db   |[0m 
[33mlocal_db   |[0m PostgreSQL Database directory appears to contain a database; Skipping initialization
[33mlocal_db   |[0m 
[33mlocal_db   |[0m 2024-01-09 21:15:41.136 UTC [1] LOG:  starting PostgreSQL 16.1 (Debian 16.1-1.pgdg120+1) on aarch64-unknown-linux-gnu, compiled by gcc (Debian 12.2.0-14) 12.2.0, 64-bit
[33mlocal_db   |[0m 2024-01-09 21:15:41.141 UTC [1] LOG:  listening on IPv4 address "0.0.0.0", port 5432
[33mlocal_db   |[0m 2024-01-09 21:15:41.141 UTC [1] LOG:  listening on IPv6 address "::", port 5432
[33mlocal_db   |[0m 2024-01-09 21:15:41.211 UTC [1] LOG:  listening on Unix socket "/var/run/postgresql/.s.PGSQL.5432"
[33mlocal_db   |[0m 2024-01-09 21:15:41.245 UTC [31] LOG:  database system was shut down at 2024-01-09 20:46:15 UTC
[33mlocal_db   |[0m 2024-01-09 21:15:41.305 UTC [1] LOG:  database system is ready to accept connections
[33mlocal_db   |[0m 2024-01-09 21:17:39.613 UTC [1] LOG:  received fast shutdown request
[33mlocal_db   |[0m 2024-01-09 21:17:39.620 UTC [1] LOG:  aborting any active transactions
[33mlocal_db   |[0m 2024-01-09 21:17:39.636 UTC [1] LOG:  background worker "logical replication launcher" (PID 34) exited with exit code 1
[33mlocal_db   |[0m 2024-01-09 21:17:39.637 UTC [29] LOG:  shutting down
[33mlocal_db   |[0m 2024-01-09 21:17:39.642 UTC [29] LOG:  checkpoint starting: shutdown immediate
[33mlocal_db   |[0m 2024-01-09 21:17:39.672 UTC [29] LOG:  checkpoint complete: wrote 3 buffers (0.0%); 0 WAL file(s) added, 0 removed, 0 recycled; write=0.011 s, sync=0.004 s, total=0.036 s; sync files=2, longest=0.002 s, average=0.002 s; distance=0 kB, estimate=0 kB; lsn=0/1946738, redo lsn=0/1946738
[33mlocal_db   |[0m 2024-01-09 21:17:39.698 UTC [1] LOG:  database system is shut down
[33mlocal_db   |[0m 
[33mlocal_db   |[0m PostgreSQL Database directory appears to contain a database; Skipping initialization
[33mlocal_db   |[0m 
[33mlocal_db   |[0m 2024-01-09 21:28:27.280 UTC [1] LOG:  starting PostgreSQL 16.1 (Debian 16.1-1.pgdg120+1) on aarch64-unknown-linux-gnu, compiled by gcc (Debian 12.2.0-14) 12.2.0, 64-bit
[33mlocal_db   |[0m 2024-01-09 21:28:27.283 UTC [1] LOG:  listening on IPv4 address "0.0.0.0", port 5432
[33mlocal_db   |[0m 2024-01-09 21:28:27.284 UTC [1] LOG:  listening on IPv6 address "::", port 5432
[33mlocal_db   |[0m 2024-01-09 21:28:27.301 UTC [1] LOG:  listening on Unix socket "/var/run/postgresql/.s.PGSQL.5432"
[33mlocal_db   |[0m 2024-01-09 21:28:27.328 UTC [30] LOG:  database system was shut down at 2024-01-09 21:17:39 UTC
[33mlocal_db   |[0m 2024-01-09 21:28:27.368 UTC [1] LOG:  database system is ready to accept connections
[33mlocal_db   |[0m 2024-01-09 21:33:27.345 UTC [28] LOG:  checkpoint starting: time
[33mlocal_db   |[0m 2024-01-09 21:33:27.390 UTC [28] LOG:  checkpoint complete: wrote 3 buffers (0.0%); 0 WAL file(s) added, 0 removed, 0 recycled; write=0.016 s, sync=0.004 s, total=0.046 s; sync files=2, longest=0.003 s, average=0.002 s; distance=0 kB, estimate=0 kB; lsn=0/1946820, redo lsn=0/19467E8
[33mlocal_db   |[0m 2024-01-09 21:33:40.862 UTC [1] LOG:  received fast shutdown request
[33mlocal_db   |[0m 2024-01-09 21:33:40.870 UTC [1] LOG:  aborting any active transactions
[33mlocal_db   |[0m 2024-01-09 21:33:40.882 UTC [1] LOG:  background worker "logical replication launcher" (PID 33) exited with exit code 1
[33mlocal_db   |[0m 2024-01-09 21:33:40.889 UTC [28] LOG:  shutting down
[33mlocal_db   |[0m 2024-01-09 21:33:40.894 UTC [28] LOG:  checkpoint starting: shutdown immediate
[33mlocal_db   |[0m 2024-01-09 21:33:40.915 UTC [28] LOG:  checkpoint complete: wrote 0 buffers (0.0%); 0 WAL file(s) added, 0 removed, 0 recycled; write=0.004 s, sync=0.001 s, total=0.026 s; sync files=0, longest=0.000 s, average=0.000 s; distance=0 kB, estimate=0 kB; lsn=0/19468D0, redo lsn=0/19468D0
[33mlocal_db   |[0m 2024-01-09 21:33:40.940 UTC [1] LOG:  database system is shut down
[33mlocal_db   |[0m 
[33mlocal_db   |[0m PostgreSQL Database directory appears to contain a database; Skipping initialization
[33mlocal_db   |[0m 
[33mlocal_db   |[0m 2024-01-09 21:39:52.401 UTC [1] LOG:  starting PostgreSQL 16.1 (Debian 16.1-1.pgdg120+1) on aarch64-unknown-linux-gnu, compiled by gcc (Debian 12.2.0-14) 12.2.0, 64-bit
[33mlocal_db   |[0m 2024-01-09 21:39:52.402 UTC [1] LOG:  listening on IPv4 address "0.0.0.0", port 5432
[33mlocal_db   |[0m 2024-01-09 21:39:52.403 UTC [1] LOG:  listening on IPv6 address "::", port 5432
[33mlocal_db   |[0m 2024-01-09 21:39:52.506 UTC [1] LOG:  listening on Unix socket "/var/run/postgresql/.s.PGSQL.5432"
[33mlocal_db   |[0m 2024-01-09 21:39:52.603 UTC [29] LOG:  database system was shut down at 2024-01-09 21:33:40 UTC
[33mlocal_db   |[0m 2024-01-09 21:39:52.636 UTC [1] LOG:  database system is ready to accept connections
[33mlocal_db   |[0m 2024-01-09 21:43:59.120 UTC [1] LOG:  received fast shutdown request
[33mlocal_db   |[0m 2024-01-09 21:43:59.129 UTC [1] LOG:  aborting any active transactions
[33mlocal_db   |[0m 2024-01-09 21:43:59.143 UTC [1] LOG:  background worker "logical replication launcher" (PID 32) exited with exit code 1
[33mlocal_db   |[0m 2024-01-09 21:43:59.148 UTC [27] LOG:  shutting down
[33mlocal_db   |[0m 2024-01-09 21:43:59.155 UTC [27] LOG:  checkpoint starting: shutdown immediate
[33mlocal_db   |[0m 2024-01-09 21:43:59.258 UTC [27] LOG:  checkpoint complete: wrote 6 buffers (0.0%); 0 WAL file(s) added, 0 removed, 0 recycled; write=0.019 s, sync=0.012 s, total=0.111 s; sync files=5, longest=0.009 s, average=0.003 s; distance=1 kB, estimate=1 kB; lsn=0/1946FF0, redo lsn=0/1946FF0
[33mlocal_db   |[0m 2024-01-09 21:43:59.285 UTC [1] LOG:  database system is shut down
[33mlocal_db   |[0m 
[33mlocal_db   |[0m PostgreSQL Database directory appears to contain a database; Skipping initialization
[33mlocal_db   |[0m 
[33mlocal_db   |[0m 2024-01-09 21:47:46.225 UTC [1] LOG:  starting PostgreSQL 16.1 (Debian 16.1-1.pgdg120+1) on aarch64-unknown-linux-gnu, compiled by gcc (Debian 12.2.0-14) 12.2.0, 64-bit
[33mlocal_db   |[0m 2024-01-09 21:47:46.226 UTC [1] LOG:  listening on IPv4 address "0.0.0.0", port 5432
[33mlocal_db   |[0m 2024-01-09 21:47:46.226 UTC [1] LOG:  listening on IPv6 address "::", port 5432
[33mlocal_db   |[0m 2024-01-09 21:47:46.247 UTC [1] LOG:  listening on Unix socket "/var/run/postgresql/.s.PGSQL.5432"
[33mlocal_db   |[0m 2024-01-09 21:47:46.290 UTC [29] LOG:  database system was shut down at 2024-01-09 21:43:59 UTC
[33mlocal_db   |[0m 2024-01-09 21:47:46.338 UTC [1] LOG:  database system is ready to accept connections
[33mlocal_db   |[0m 2024-01-09 21:52:46.287 UTC [27] LOG:  checkpoint starting: time
[33mlocal_db   |[0m 2024-01-09 21:52:46.325 UTC [27] LOG:  checkpoint complete: wrote 3 buffers (0.0%); 0 WAL file(s) added, 0 removed, 0 recycled; write=0.013 s, sync=0.004 s, total=0.039 s; sync files=2, longest=0.002 s, average=0.002 s; distance=0 kB, estimate=0 kB; lsn=0/19470D8, redo lsn=0/19470A0
[33mlocal_db   |[0m 2024-01-10 08:17:54.986 UTC [27] LOG:  checkpoint starting: time
[33mlocal_db   |[0m 2024-01-10 08:17:55.345 UTC [27] LOG:  checkpoint complete: wrote 4 buffers (0.0%); 0 WAL file(s) added, 0 removed, 0 recycled; write=0.322 s, sync=0.011 s, total=0.359 s; sync files=4, longest=0.009 s, average=0.003 s; distance=1 kB, estimate=1 kB; lsn=0/1947808, redo lsn=0/19477D0
[33mlocal_db   |[0m 2024-01-10 10:02:57.020 UTC [27] LOG:  checkpoint starting: time
[33mlocal_db   |[0m 2024-01-10 10:02:57.526 UTC [27] LOG:  checkpoint complete: wrote 4 buffers (0.0%); 0 WAL file(s) added, 0 removed, 0 recycled; write=0.421 s, sync=0.011 s, total=0.509 s; sync files=4, longest=0.009 s, average=0.003 s; distance=1 kB, estimate=1 kB; lsn=0/1947F78, redo lsn=0/1947F40
[33mlocal_db   |[0m 2024-01-10 11:47:58.832 UTC [27] LOG:  checkpoint starting: time
[33mlocal_db   |[0m 2024-01-10 11:47:59.176 UTC [27] LOG:  checkpoint complete: wrote 4 buffers (0.0%); 0 WAL file(s) added, 0 removed, 0 recycled; write=0.311 s, sync=0.010 s, total=0.344 s; sync files=4, longest=0.008 s, average=0.003 s; distance=1 kB, estimate=1 kB; lsn=0/1948750, redo lsn=0/1948718
[33mlocal_db   |[0m 2024-01-10 13:17:59.401 UTC [27] LOG:  checkpoint starting: time
[33mlocal_db   |[0m 2024-01-10 13:17:59.745 UTC [27] LOG:  checkpoint complete: wrote 4 buffers (0.0%); 0 WAL file(s) added, 0 removed, 0 recycled; write=0.311 s, sync=0.010 s, total=0.344 s; sync files=4, longest=0.008 s, average=0.003 s; distance=2 kB, estimate=2 kB; lsn=0/1948F50, redo lsn=0/1948F18
[33mlocal_db   |[0m 2024-01-10 14:18:00.448 UTC [27] LOG:  checkpoint starting: time
[33mlocal_db   |[0m 2024-01-10 14:18:00.925 UTC [27] LOG:  checkpoint complete: wrote 4 buffers (0.0%); 0 WAL file(s) added, 0 removed, 0 recycled; write=0.345 s, sync=0.010 s, total=0.478 s; sync files=4, longest=0.008 s, average=0.003 s; distance=2 kB, estimate=2 kB; lsn=0/19497A0, redo lsn=0/1949768
[33mlocal_db   |[0m 2024-01-10 16:03:02.263 UTC [27] LOG:  checkpoint starting: time
[33mlocal_db   |[0m 2024-01-10 16:03:02.607 UTC [27] LOG:  checkpoint complete: wrote 4 buffers (0.0%); 0 WAL file(s) added, 0 removed, 0 recycled; write=0.312 s, sync=0.010 s, total=0.344 s; sync files=4, longest=0.009 s, average=0.003 s; distance=2 kB, estimate=2 kB; lsn=0/194A048, redo lsn=0/1949FF8
[33mlocal_db   |[0m 2024-01-10 17:48:04.099 UTC [27] LOG:  checkpoint starting: time
[33mlocal_db   |[0m 2024-01-10 17:48:04.443 UTC [27] LOG:  checkpoint complete: wrote 4 buffers (0.0%); 0 WAL file(s) added, 0 removed, 0 recycled; write=0.311 s, sync=0.011 s, total=0.344 s; sync files=4, longest=0.009 s, average=0.003 s; distance=2 kB, estimate=2 kB; lsn=0/194A928, redo lsn=0/194A8F0
[33mlocal_db   |[0m 2024-01-10 19:18:05.544 UTC [27] LOG:  checkpoint starting: time
[33mlocal_db   |[0m 2024-01-10 19:18:05.943 UTC [27] LOG:  checkpoint complete: wrote 4 buffers (0.0%); 0 WAL file(s) added, 0 removed, 0 recycled; write=0.312 s, sync=0.064 s, total=0.399 s; sync files=4, longest=0.062 s, average=0.016 s; distance=2 kB, estimate=2 kB; lsn=0/194B248, redo lsn=0/194B210
[33mlocal_db   |[0m 2024-01-11 08:18:17.899 UTC [27] LOG:  checkpoint starting: time
[33mlocal_db   |[0m 2024-01-11 08:18:18.241 UTC [27] LOG:  checkpoint complete: wrote 4 buffers (0.0%); 0 WAL file(s) added, 0 removed, 0 recycled; write=0.311 s, sync=0.010 s, total=0.342 s; sync files=4, longest=0.009 s, average=0.003 s; distance=2 kB, estimate=2 kB; lsn=0/194BBB8, redo lsn=0/194BB80
[33mlocal_db   |[0m 2024-01-11 10:03:18.676 UTC [27] LOG:  checkpoint starting: time
[33mlocal_db   |[0m 2024-01-11 10:03:19.022 UTC [27] LOG:  checkpoint complete: wrote 4 buffers (0.0%); 0 WAL file(s) added, 0 removed, 0 recycled; write=0.311 s, sync=0.011 s, total=0.346 s; sync files=4, longest=0.009 s, average=0.003 s; distance=2 kB, estimate=2 kB; lsn=0/194C580, redo lsn=0/194C548
[33mlocal_db   |[0m 2024-01-11 11:48:19.780 UTC [27] LOG:  checkpoint starting: time
[33mlocal_db   |[0m 2024-01-11 11:48:20.126 UTC [27] LOG:  checkpoint complete: wrote 4 buffers (0.0%); 0 WAL file(s) added, 0 removed, 0 recycled; write=0.312 s, sync=0.009 s, total=0.346 s; sync files=4, longest=0.007 s, average=0.003 s; distance=2 kB, estimate=2 kB; lsn=0/194CF80, redo lsn=0/194CF48
[33mlocal_db   |[0m 2024-01-11 13:18:20.083 UTC [27] LOG:  checkpoint starting: time
[33mlocal_db   |[0m 2024-01-11 13:18:20.431 UTC [27] LOG:  checkpoint complete: wrote 4 buffers (0.0%); 0 WAL file(s) added, 0 removed, 0 recycled; write=0.311 s, sync=0.010 s, total=0.349 s; sync files=4, longest=0.007 s, average=0.003 s; distance=2 kB, estimate=2 kB; lsn=0/194D9C0, redo lsn=0/194D988
[33mlocal_db   |[0m 2024-01-11 14:18:21.064 UTC [27] LOG:  checkpoint starting: time
[33mlocal_db   |[0m 2024-01-11 14:18:21.409 UTC [27] LOG:  checkpoint complete: wrote 4 buffers (0.0%); 0 WAL file(s) added, 0 removed, 0 recycled; write=0.311 s, sync=0.011 s, total=0.346 s; sync files=4, longest=0.008 s, average=0.003 s; distance=2 kB, estimate=2 kB; lsn=0/194E468, redo lsn=0/194E430
[33mlocal_db   |[0m 2024-01-11 16:03:22.929 UTC [27] LOG:  checkpoint starting: time
[33mlocal_db   |[0m 2024-01-11 16:03:23.303 UTC [27] LOG:  checkpoint complete: wrote 4 buffers (0.0%); 0 WAL file(s) added, 0 removed, 0 recycled; write=0.324 s, sync=0.010 s, total=0.375 s; sync files=4, longest=0.008 s, average=0.003 s; distance=2 kB, estimate=2 kB; lsn=0/194EF38, redo lsn=0/194EF00
[33mlocal_db   |[0m 2024-01-11 17:39:18.476 UTC [1] LOG:  received fast shutdown request
[33mlocal_db   |[0m 2024-01-11 17:39:18.503 UTC [1] LOG:  aborting any active transactions
[33mlocal_db   |[0m 2024-01-11 17:39:18.546 UTC [1] LOG:  background worker "logical replication launcher" (PID 32) exited with exit code 1
[33mlocal_db   |[0m 2024-01-11 17:39:18.550 UTC [27] LOG:  shutting down
[33mlocal_db   |[0m 2024-01-11 17:39:18.557 UTC [27] LOG:  checkpoint starting: shutdown immediate
[33mlocal_db   |[0m 2024-01-11 17:39:18.588 UTC [27] LOG:  checkpoint complete: wrote 0 buffers (0.0%); 0 WAL file(s) added, 0 removed, 0 recycled; write=0.005 s, sync=0.001 s, total=0.039 s; sync files=0, longest=0.000 s, average=0.000 s; distance=0 kB, estimate=2 kB; lsn=0/194EFE8, redo lsn=0/194EFE8
[33mlocal_db   |[0m 2024-01-11 17:39:18.629 UTC [1] LOG:  database system is shut down
[33mlocal_db   |[0m 
[33mlocal_db   |[0m PostgreSQL Database directory appears to contain a database; Skipping initialization
[33mlocal_db   |[0m 
[33mlocal_db   |[0m 2024-01-11 17:39:43.309 UTC [1] LOG:  starting PostgreSQL 16.1 (Debian 16.1-1.pgdg120+1) on aarch64-unknown-linux-gnu, compiled by gcc (Debian 12.2.0-14) 12.2.0, 64-bit
[33mlocal_db   |[0m 2024-01-11 17:39:43.312 UTC [1] LOG:  listening on IPv4 address "0.0.0.0", port 5432
[33mlocal_db   |[0m 2024-01-11 17:39:43.313 UTC [1] LOG:  listening on IPv6 address "::", port 5432
[33mlocal_db   |[0m 2024-01-11 17:39:43.330 UTC [1] LOG:  listening on Unix socket "/var/run/postgresql/.s.PGSQL.5432"
[33mlocal_db   |[0m 2024-01-11 17:39:43.414 UTC [29] LOG:  database system was shut down at 2024-01-11 17:39:18 UTC
[33mlocal_db   |[0m 2024-01-11 17:39:43.467 UTC [1] LOG:  database system is ready to accept connections
[33mlocal_db   |[0m 2024-01-11 17:44:43.473 UTC [27] LOG:  checkpoint starting: time
[33mlocal_db   |[0m 2024-01-11 17:44:43.677 UTC [27] LOG:  checkpoint complete: wrote 4 buffers (0.0%); 0 WAL file(s) added, 0 removed, 0 recycled; write=0.118 s, sync=0.010 s, total=0.205 s; sync files=3, longest=0.006 s, average=0.004 s; distance=0 kB, estimate=0 kB; lsn=0/194F0D0, redo lsn=0/194F098
[33mlocal_db   |[0m 2024-01-11 18:19:44.024 UTC [27] LOG:  checkpoint starting: time
[33mlocal_db   |[0m 2024-01-11 18:19:44.368 UTC [27] LOG:  checkpoint complete: wrote 4 buffers (0.0%); 0 WAL file(s) added, 0 removed, 0 recycled; write=0.311 s, sync=0.010 s, total=0.344 s; sync files=4, longest=0.008 s, average=0.003 s; distance=2 kB, estimate=2 kB; lsn=0/194FCA8, redo lsn=0/194FC70
[33mlocal_db   |[0m 2024-01-11 18:25:19.177 UTC [1] LOG:  received fast shutdown request
[33mlocal_db   |[0m 2024-01-11 18:25:19.185 UTC [1] LOG:  aborting any active transactions
[33mlocal_db   |[0m 2024-01-11 18:25:19.203 UTC [1] LOG:  background worker "logical replication launcher" (PID 32) exited with exit code 1
[33mlocal_db   |[0m 2024-01-11 18:25:19.211 UTC [27] LOG:  shutting down
[33mlocal_db   |[0m 2024-01-11 18:25:19.219 UTC [27] LOG:  checkpoint starting: shutdown immediate
[33mlocal_db   |[0m 2024-01-11 18:25:19.249 UTC [27] LOG:  checkpoint complete: wrote 0 buffers (0.0%); 0 WAL file(s) added, 0 removed, 0 recycled; write=0.004 s, sync=0.001 s, total=0.039 s; sync files=0, longest=0.000 s, average=0.000 s; distance=0 kB, estimate=2 kB; lsn=0/194FD58, redo lsn=0/194FD58
[33mlocal_db   |[0m 2024-01-11 18:25:19.279 UTC [1] LOG:  database system is shut down
[33mlocal_db   |[0m 
[33mlocal_db   |[0m PostgreSQL Database directory appears to contain a database; Skipping initialization
[33mlocal_db   |[0m 
[33mlocal_db   |[0m 2024-01-11 18:29:01.379 UTC [1] LOG:  starting PostgreSQL 16.1 (Debian 16.1-1.pgdg120+1) on aarch64-unknown-linux-gnu, compiled by gcc (Debian 12.2.0-14) 12.2.0, 64-bit
[33mlocal_db   |[0m 2024-01-11 18:29:01.382 UTC [1] LOG:  listening on IPv4 address "0.0.0.0", port 5432
[33mlocal_db   |[0m 2024-01-11 18:29:01.382 UTC [1] LOG:  listening on IPv6 address "::", port 5432
[33mlocal_db   |[0m 2024-01-11 18:29:01.403 UTC [1] LOG:  listening on Unix socket "/var/run/postgresql/.s.PGSQL.5432"
[33mlocal_db   |[0m 2024-01-11 18:29:01.438 UTC [30] LOG:  database system was shut down at 2024-01-11 18:25:19 UTC
[33mlocal_db   |[0m 2024-01-11 18:29:01.476 UTC [1] LOG:  database system is ready to accept connections
[33mlocal_db   |[0m 2024-01-11 18:31:23.783 UTC [1] LOG:  received fast shutdown request
[33mlocal_db   |[0m 2024-01-11 18:31:23.792 UTC [1] LOG:  aborting any active transactions
[33mlocal_db   |[0m 2024-01-11 18:31:23.803 UTC [1] LOG:  background worker "logical replication launcher" (PID 33) exited with exit code 1
[33mlocal_db   |[0m 2024-01-11 18:31:23.806 UTC [28] LOG:  shutting down
[33mlocal_db   |[0m 2024-01-11 18:31:23.812 UTC [28] LOG:  checkpoint starting: shutdown immediate
[33mlocal_db   |[0m 2024-01-11 18:31:23.848 UTC [28] LOG:  checkpoint complete: wrote 3 buffers (0.0%); 0 WAL file(s) added, 0 removed, 0 recycled; write=0.011 s, sync=0.004 s, total=0.043 s; sync files=2, longest=0.002 s, average=0.002 s; distance=0 kB, estimate=0 kB; lsn=0/194FE08, redo lsn=0/194FE08
[33mlocal_db   |[0m 2024-01-11 18:31:23.873 UTC [1] LOG:  database system is shut down
[33mlocal_db   |[0m 
[33mlocal_db   |[0m PostgreSQL Database directory appears to contain a database; Skipping initialization
[33mlocal_db   |[0m 
[33mlocal_db   |[0m 2024-01-11 18:34:25.174 UTC [1] LOG:  starting PostgreSQL 16.1 (Debian 16.1-1.pgdg120+1) on aarch64-unknown-linux-gnu, compiled by gcc (Debian 12.2.0-14) 12.2.0, 64-bit
[33mlocal_db   |[0m 2024-01-11 18:34:25.175 UTC [1] LOG:  listening on IPv4 address "0.0.0.0", port 5432
[33mlocal_db   |[0m 2024-01-11 18:34:25.175 UTC [1] LOG:  listening on IPv6 address "::", port 5432
[33mlocal_db   |[0m 2024-01-11 18:34:25.212 UTC [1] LOG:  listening on Unix socket "/var/run/postgresql/.s.PGSQL.5432"
[33mlocal_db   |[0m 2024-01-11 18:34:25.239 UTC [30] LOG:  database system was shut down at 2024-01-11 18:31:23 UTC
[33mlocal_db   |[0m 2024-01-11 18:34:25.270 UTC [1] LOG:  database system is ready to accept connections
[33mlocal_db   |[0m 2024-01-11 18:39:25.336 UTC [28] LOG:  checkpoint starting: time
[33mlocal_db   |[0m 2024-01-11 18:39:25.380 UTC [28] LOG:  checkpoint complete: wrote 3 buffers (0.0%); 0 WAL file(s) added, 0 removed, 0 recycled; write=0.016 s, sync=0.005 s, total=0.045 s; sync files=2, longest=0.003 s, average=0.003 s; distance=0 kB, estimate=0 kB; lsn=0/194FEF0, redo lsn=0/194FEB8
[33mlocal_db   |[0m 2024-01-11 18:43:07.655 UTC [1] LOG:  received fast shutdown request
[33mlocal_db   |[0m 2024-01-11 18:43:07.663 UTC [1] LOG:  aborting any active transactions
[33mlocal_db   |[0m 2024-01-11 18:43:07.676 UTC [1] LOG:  background worker "logical replication launcher" (PID 33) exited with exit code 1
[33mlocal_db   |[0m 2024-01-11 18:43:07.682 UTC [28] LOG:  shutting down
[33mlocal_db   |[0m 2024-01-11 18:43:07.687 UTC [28] LOG:  checkpoint starting: shutdown immediate
[33mlocal_db   |[0m 2024-01-11 18:43:07.710 UTC [28] LOG:  checkpoint complete: wrote 0 buffers (0.0%); 0 WAL file(s) added, 0 removed, 0 recycled; write=0.004 s, sync=0.001 s, total=0.029 s; sync files=0, longest=0.000 s, average=0.000 s; distance=0 kB, estimate=0 kB; lsn=0/194FFA0, redo lsn=0/194FFA0
[33mlocal_db   |[0m 2024-01-11 18:43:07.735 UTC [1] LOG:  database system is shut down
[33mlocal_db   |[0m 
[33mlocal_db   |[0m PostgreSQL Database directory appears to contain a database; Skipping initialization
[33mlocal_db   |[0m 
[33mlocal_db   |[0m 2024-01-11 18:46:08.554 UTC [1] LOG:  starting PostgreSQL 16.1 (Debian 16.1-1.pgdg120+1) on aarch64-unknown-linux-gnu, compiled by gcc (Debian 12.2.0-14) 12.2.0, 64-bit
[33mlocal_db   |[0m 2024-01-11 18:46:08.554 UTC [1] LOG:  listening on IPv4 address "0.0.0.0", port 5432
[33mlocal_db   |[0m 2024-01-11 18:46:08.555 UTC [1] LOG:  listening on IPv6 address "::", port 5432
[33mlocal_db   |[0m 2024-01-11 18:46:08.590 UTC [1] LOG:  listening on Unix socket "/var/run/postgresql/.s.PGSQL.5432"
[33mlocal_db   |[0m 2024-01-11 18:46:08.617 UTC [30] LOG:  database system was shut down at 2024-01-11 18:43:07 UTC
[33mlocal_db   |[0m 2024-01-11 18:46:08.647 UTC [1] LOG:  database system is ready to accept connections
[33mlocal_db   |[0m 2024-01-11 18:50:18.451 UTC [1] LOG:  received fast shutdown request
[33mlocal_db   |[0m 2024-01-11 18:50:18.460 UTC [1] LOG:  aborting any active transactions
[33mlocal_db   |[0m 2024-01-11 18:50:18.474 UTC [1] LOG:  background worker "logical replication launcher" (PID 33) exited with exit code 1
[33mlocal_db   |[0m 2024-01-11 18:50:18.477 UTC [28] LOG:  shutting down
[33mlocal_db   |[0m 2024-01-11 18:50:18.484 UTC [28] LOG:  checkpoint starting: shutdown immediate
[33mlocal_db   |[0m 2024-01-11 18:50:18.522 UTC [28] LOG:  checkpoint complete: wrote 3 buffers (0.0%); 0 WAL file(s) added, 0 removed, 0 recycled; write=0.011 s, sync=0.004 s, total=0.044 s; sync files=2, longest=0.002 s, average=0.002 s; distance=0 kB, estimate=0 kB; lsn=0/1950068, redo lsn=0/1950068
[33mlocal_db   |[0m 2024-01-11 18:50:18.548 UTC [1] LOG:  database system is shut down
[33mlocal_db   |[0m 
[33mlocal_db   |[0m PostgreSQL Database directory appears to contain a database; Skipping initialization
[33mlocal_db   |[0m 
[33mlocal_db   |[0m 2024-01-11 19:00:53.822 UTC [1] LOG:  starting PostgreSQL 16.1 (Debian 16.1-1.pgdg120+1) on aarch64-unknown-linux-gnu, compiled by gcc (Debian 12.2.0-14) 12.2.0, 64-bit
[33mlocal_db   |[0m 2024-01-11 19:00:53.823 UTC [1] LOG:  listening on IPv4 address "0.0.0.0", port 5432
[33mlocal_db   |[0m 2024-01-11 19:00:53.824 UTC [1] LOG:  listening on IPv6 address "::", port 5432
[33mlocal_db   |[0m 2024-01-11 19:00:53.862 UTC [1] LOG:  listening on Unix socket "/var/run/postgresql/.s.PGSQL.5432"
[33mlocal_db   |[0m 2024-01-11 19:00:53.889 UTC [29] LOG:  database system was shut down at 2024-01-11 18:50:18 UTC
[33mlocal_db   |[0m 2024-01-11 19:00:53.921 UTC [1] LOG:  database system is ready to accept connections
[33mlocal_db   |[0m 2024-01-11 19:05:53.945 UTC [27] LOG:  checkpoint starting: time
[33mlocal_db   |[0m 2024-01-11 19:05:53.990 UTC [27] LOG:  checkpoint complete: wrote 3 buffers (0.0%); 0 WAL file(s) added, 0 removed, 0 recycled; write=0.017 s, sync=0.005 s, total=0.046 s; sync files=2, longest=0.003 s, average=0.003 s; distance=0 kB, estimate=0 kB; lsn=0/1950150, redo lsn=0/1950118
[33mlocal_db   |[0m 2024-01-12 07:16:03.353 UTC [27] LOG:  checkpoint starting: time
[33mlocal_db   |[0m 2024-01-12 07:16:03.707 UTC [27] LOG:  checkpoint complete: wrote 4 buffers (0.0%); 0 WAL file(s) added, 0 removed, 0 recycled; write=0.321 s, sync=0.010 s, total=0.354 s; sync files=4, longest=0.008 s, average=0.003 s; distance=3 kB, estimate=3 kB; lsn=0/1950DB8, redo lsn=0/1950D80
[36mflask-rest-api |[0m  * Serving Flask app 'RestService' (lazy loading)
[36mflask-rest-api |[0m  * Environment: production
[36mflask-rest-api |[0m    WARNING: This is a development server. Do not use it in a production deployment.
[36mflask-rest-api |[0m    Use a production WSGI server instead.
[36mflask-rest-api |[0m  * Debug mode: on
[36mflask-rest-api |[0m WARNING:werkzeug: * Running on all addresses.
[36mflask-rest-api |[0m    WARNING: This is a development server. Do not use it in a production deployment.
[36mflask-rest-api |[0m INFO:werkzeug: * Running on https://172.18.0.3:5000/ (Press CTRL+C to quit)
[36mflask-rest-api |[0m INFO:werkzeug: * Restarting with stat
[36mflask-rest-api |[0m WARNING:werkzeug: * Debugger is active!
[36mflask-rest-api |[0m INFO:werkzeug: * Debugger PIN: 135-005-259
[36mflask-rest-api |[0m INFO:werkzeug:141.87.60.118 - - [12/Jan/2024 13:50:45] "[35m[1mPOST /AddGraphData HTTP/1.1[0m" 500 -
[36mflask-rest-api |[0m Traceback (most recent call last):
[36mflask-rest-api |[0m   File "/usr/lib/python3.11/site-packages/flask/app.py", line 2088, in __call__
[36mflask-rest-api |[0m     return self.wsgi_app(environ, start_response)
[36mflask-rest-api |[0m   File "/usr/lib/python3.11/site-packages/flask/app.py", line 2073, in wsgi_app
[36mflask-rest-api |[0m     response = self.handle_exception(e)
[36mflask-rest-api |[0m   File "/usr/lib/python3.11/site-packages/flask_cors/extension.py", line 165, in wrapped_function
[36mflask-rest-api |[0m     return cors_after_request(app.make_response(f(*args, **kwargs)))
[36mflask-rest-api |[0m   File "/usr/lib/python3.11/site-packages/flask/app.py", line 2070, in wsgi_app
[36mflask-rest-api |[0m     response = self.full_dispatch_request()
[36mflask-rest-api |[0m   File "/usr/lib/python3.11/site-packages/flask/app.py", line 1515, in full_dispatch_request
[36mflask-rest-api |[0m     rv = self.handle_user_exception(e)
[36mflask-rest-api |[0m   File "/usr/lib/python3.11/site-packages/flask_cors/extension.py", line 165, in wrapped_function
[36mflask-rest-api |[0m     return cors_after_request(app.make_response(f(*args, **kwargs)))
[36mflask-rest-api |[0m   File "/usr/lib/python3.11/site-packages/flask/app.py", line 1513, in full_dispatch_request
[36mflask-rest-api |[0m     rv = self.dispatch_request()
[36mflask-rest-api |[0m   File "/usr/lib/python3.11/site-packages/flask/app.py", line 1499, in dispatch_request
[36mflask-rest-api |[0m     return self.ensure_sync(self.view_functions[rule.endpoint])(**req.view_args)
[36mflask-rest-api |[0m   File "/app/RestService.py", line 71, in add_graph_data
[36mflask-rest-api |[0m     time_stamp = data.get('time_stamp')
[36mflask-rest-api |[0m AttributeError: 'NoneType' object has no attribute 'get'
[36mflask-rest-api |[0m INFO:werkzeug:141.87.60.118 - - [12/Jan/2024 13:51:24] "[35m[1mPOST /AddGraphData HTTP/1.1[0m" 500 -
[36mflask-rest-api |[0m Traceback (most recent call last):
[36mflask-rest-api |[0m   File "/usr/lib/python3.11/site-packages/flask/app.py", line 2088, in __call__
[36mflask-rest-api |[0m     return self.wsgi_app(environ, start_response)
[36mflask-rest-api |[0m   File "/usr/lib/python3.11/site-packages/flask/app.py", line 2073, in wsgi_app
[36mflask-rest-api |[0m     response = self.handle_exception(e)
[36mflask-rest-api |[0m   File "/usr/lib/python3.11/site-packages/flask_cors/extension.py", line 165, in wrapped_function
[36mflask-rest-api |[0m     return cors_after_request(app.make_response(f(*args, **kwargs)))
[36mflask-rest-api |[0m   File "/usr/lib/python3.11/site-packages/flask/app.py", line 2070, in wsgi_app
[36mflask-rest-api |[0m     response = self.full_dispatch_request()
[36mflask-rest-api |[0m   File "/usr/lib/python3.11/site-packages/flask/app.py", line 1515, in full_dispatch_request
[36mflask-rest-api |[0m     rv = self.handle_user_exception(e)
[36mflask-rest-api |[0m   File "/usr/lib/python3.11/site-packages/flask_cors/extension.py", line 165, in wrapped_function
[36mflask-rest-api |[0m     return cors_after_request(app.make_response(f(*args, **kwargs)))
[36mflask-rest-api |[0m   File "/usr/lib/python3.11/site-packages/flask/app.py", line 1513, in full_dispatch_request
[36mflask-rest-api |[0m     rv = self.dispatch_request()
[36mflask-rest-api |[0m   File "/usr/lib/python3.11/site-packages/flask/app.py", line 1499, in dispatch_request
[36mflask-rest-api |[0m     return self.ensure_sync(self.view_functions[rule.endpoint])(**req.view_args)
[36mflask-rest-api |[0m   File "/app/RestService.py", line 71, in add_graph_data
[36mflask-rest-api |[0m     time_stamp = data.get('time_stamp')
[36mflask-rest-api |[0m AttributeError: 'NoneType' object has no attribute 'get'
[36mflask-rest-api |[0m INFO:werkzeug:141.87.60.118 - - [12/Jan/2024 13:52:24] "[35m[1mPOST /AddGraphData HTTP/1.1[0m" 500 -
[36mflask-rest-api |[0m Traceback (most recent call last):
[36mflask-rest-api |[0m   File "/usr/lib/python3.11/site-packages/flask/app.py", line 2088, in __call__
[36mflask-rest-api |[0m     return self.wsgi_app(environ, start_response)
[36mflask-rest-api |[0m   File "/usr/lib/python3.11/site-packages/flask/app.py", line 2073, in wsgi_app
[36mflask-rest-api |[0m     response = self.handle_exception(e)
[36mflask-rest-api |[0m   File "/usr/lib/python3.11/site-packages/flask_cors/extension.py", line 165, in wrapped_function
[36mflask-rest-api |[0m     return cors_after_request(app.make_response(f(*args, **kwargs)))
[36mflask-rest-api |[0m   File "/usr/lib/python3.11/site-packages/flask/app.py", line 2070, in wsgi_app
[36mflask-rest-api |[0m     response = self.full_dispatch_request()
[36mflask-rest-api |[0m   File "/usr/lib/python3.11/site-packages/flask/app.py", line 1515, in full_dispatch_request
[36mflask-rest-api |[0m     rv = self.handle_user_exception(e)
[36mflask-rest-api |[0m   File "/usr/lib/python3.11/site-packages/flask_cors/extension.py", line 165, in wrapped_function
[36mflask-rest-api |[0m     return cors_after_request(app.make_response(f(*args, **kwargs)))
[36mflask-rest-api |[0m   File "/usr/lib/python3.11/site-packages/flask/app.py", line 1513, in full_dispatch_request
[36mflask-rest-api |[0m     rv = self.dispatch_request()
[36mflask-rest-api |[0m   File "/usr/lib/python3.11/site-packages/flask/app.py", line 1499, in dispatch_request
[36mflask-rest-api |[0m     return self.ensure_sync(self.view_functions[rule.endpoint])(**req.view_args)
[36mflask-rest-api |[0m   File "/app/RestService.py", line 71, in add_graph_data
[36mflask-rest-api |[0m     time_stamp = data.get('time_stamp')
[36mflask-rest-api |[0m AttributeError: 'NoneType' object has no attribute 'get'
[36mflask-rest-api |[0m INFO:werkzeug:141.87.60.118 - - [12/Jan/2024 13:53:01] "GET /GetGraphData HTTP/1.1" 200 -
[36mflask-rest-api |[0m INFO:werkzeug:141.87.60.118 - - [12/Jan/2024 13:54:06] "[31m[1mPOST /AddGraphData HTTP/1.1[0m" 400 -
[36mflask-rest-api |[0m INFO:werkzeug:141.87.60.118 - - [12/Jan/2024 13:54:40] "[35m[1mPOST /AddGraphData HTTP/1.1[0m" 500 -
[36mflask-rest-api |[0m Traceback (most recent call last):
[36mflask-rest-api |[0m   File "/usr/lib/python3.11/site-packages/flask/app.py", line 2088, in __call__
[36mflask-rest-api |[0m     return self.wsgi_app(environ, start_response)
[36mflask-rest-api |[0m   File "/usr/lib/python3.11/site-packages/flask/app.py", line 2073, in wsgi_app
[36mflask-rest-api |[0m     response = self.handle_exception(e)
[36mflask-rest-api |[0m   File "/usr/lib/python3.11/site-packages/flask_cors/extension.py", line 165, in wrapped_function
[36mflask-rest-api |[0m     return cors_after_request(app.make_response(f(*args, **kwargs)))
[36mflask-rest-api |[0m   File "/usr/lib/python3.11/site-packages/flask/app.py", line 2070, in wsgi_app
[36mflask-rest-api |[0m     response = self.full_dispatch_request()
[36mflask-rest-api |[0m   File "/usr/lib/python3.11/site-packages/flask/app.py", line 1515, in full_dispatch_request
[36mflask-rest-api |[0m     rv = self.handle_user_exception(e)
[36mflask-rest-api |[0m   File "/usr/lib/python3.11/site-packages/flask_cors/extension.py", line 165, in wrapped_function
[36mflask-rest-api |[0m     return cors_after_request(app.make_response(f(*args, **kwargs)))
[36mflask-rest-api |[0m   File "/usr/lib/python3.11/site-packages/flask/app.py", line 1513, in full_dispatch_request
[36mflask-rest-api |[0m     rv = self.dispatch_request()
[36mflask-rest-api |[0m   File "/usr/lib/python3.11/site-packages/flask/app.py", line 1499, in dispatch_request
[36mflask-rest-api |[0m     return self.ensure_sync(self.view_functions[rule.endpoint])(**req.view_args)
[36mflask-rest-api |[0m   File "/app/RestService.py", line 71, in add_graph_data
[36mflask-rest-api |[0m     time_stamp = data.get('time_stamp')
[36mflask-rest-api |[0m AttributeError: 'NoneType' object has no attribute 'get'
[36mflask-rest-api |[0m INFO:werkzeug:141.87.60.118 - - [12/Jan/2024 13:56:54] "[35m[1mPOST /AddGraphData HTTP/1.1[0m" 500 -
[36mflask-rest-api |[0m Traceback (most recent call last):
[36mflask-rest-api |[0m   File "/usr/lib/python3.11/site-packages/flask/app.py", line 2088, in __call__
[36mflask-rest-api |[0m     return self.wsgi_app(environ, start_response)
[36mflask-rest-api |[0m   File "/usr/lib/python3.11/site-packages/flask/app.py", line 2073, in wsgi_app
[36mflask-rest-api |[0m     response = self.handle_exception(e)
[36mflask-rest-api |[0m   File "/usr/lib/python3.11/site-packages/flask_cors/extension.py", line 165, in wrapped_function
[36mflask-rest-api |[0m     return cors_after_request(app.make_response(f(*args, **kwargs)))
[36mflask-rest-api |[0m   File "/usr/lib/python3.11/site-packages/flask/app.py", line 2070, in wsgi_app
[36mflask-rest-api |[0m     response = self.full_dispatch_request()
[36mflask-rest-api |[0m   File "/usr/lib/python3.11/site-packages/flask/app.py", line 1515, in full_dispatch_request
[36mflask-rest-api |[0m     rv = self.handle_user_exception(e)
[36mflask-rest-api |[0m   File "/usr/lib/python3.11/site-packages/flask_cors/extension.py", line 165, in wrapped_function
[36mflask-rest-api |[0m     return cors_after_request(app.make_response(f(*args, **kwargs)))
[36mflask-rest-api |[0m   File "/usr/lib/python3.11/site-packages/flask/app.py", line 1513, in full_dispatch_request
[36mflask-rest-api |[0m     rv = self.dispatch_request()
[36mflask-rest-api |[0m   File "/usr/lib/python3.11/site-packages/flask/app.py", line 1499, in dispatch_request
[36mflask-rest-api |[0m     return self.ensure_sync(self.view_functions[rule.endpoint])(**req.view_args)
[36mflask-rest-api |[0m   File "/app/RestService.py", line 71, in add_graph_data
[36mflask-rest-api |[0m     time_stamp = data.get('time_stamp')
[36mflask-rest-api |[0m AttributeError: 'NoneType' object has no attribute 'get'
[36mflask-rest-api |[0m INFO:werkzeug:141.87.60.118 - - [12/Jan/2024 13:57:24] "[35m[1mPOST /AddGraphData HTTP/1.1[0m" 500 -
[36mflask-rest-api |[0m Traceback (most recent call last):
[36mflask-rest-api |[0m   File "/usr/lib/python3.11/site-packages/flask/app.py", line 2088, in __call__
[36mflask-rest-api |[0m     return self.wsgi_app(environ, start_response)
[36mflask-rest-api |[0m   File "/usr/lib/python3.11/site-packages/flask/app.py", line 2073, in wsgi_app
[36mflask-rest-api |[0m     response = self.handle_exception(e)
[36mflask-rest-api |[0m   File "/usr/lib/python3.11/site-packages/flask_cors/extension.py", line 165, in wrapped_function
[36mflask-rest-api |[0m     return cors_after_request(app.make_response(f(*args, **kwargs)))
[36mflask-rest-api |[0m   File "/usr/lib/python3.11/site-packages/flask/app.py", line 2070, in wsgi_app
[36mflask-rest-api |[0m     response = self.full_dispatch_request()
[36mflask-rest-api |[0m   File "/usr/lib/python3.11/site-packages/flask/app.py", line 1515, in full_dispatch_request
[36mflask-rest-api |[0m     rv = self.handle_user_exception(e)
[36mflask-rest-api |[0m   File "/usr/lib/python3.11/site-packages/flask_cors/extension.py", line 165, in wrapped_function
[36mflask-rest-api |[0m     return cors_after_request(app.make_response(f(*args, **kwargs)))
[36mflask-rest-api |[0m   File "/usr/lib/python3.11/site-packages/flask/app.py", line 1513, in full_dispatch_request
[36mflask-rest-api |[0m     rv = self.dispatch_request()
[36mflask-rest-api |[0m   File "/usr/lib/python3.11/site-packages/flask/app.py", line 1499, in dispatch_request
[36mflask-rest-api |[0m     return self.ensure_sync(self.view_functions[rule.endpoint])(**req.view_args)
[36mflask-rest-api |[0m   File "/app/RestService.py", line 71, in add_graph_data
[36mflask-rest-api |[0m     time_stamp = data.get('time_stamp')
[36mflask-rest-api |[0m AttributeError: 'NoneType' object has no attribute 'get'
[36mflask-rest-api |[0m INFO:werkzeug:141.87.60.118 - - [12/Jan/2024 14:00:03] "[31m[1mPOST /AddGraphData HTTP/1.1[0m" 400 -
[36mflask-rest-api |[0m INFO:werkzeug:141.87.60.118 - - [12/Jan/2024 14:04:00] "POST /AddGraphData HTTP/1.1" 200 -
[36mflask-rest-api |[0m INFO:werkzeug:141.87.60.118 - - [12/Jan/2024 14:04:11] "GET /GetGraphData HTTP/1.1" 200 -
[36mflask-rest-api |[0m INFO:werkzeug:141.87.60.118 - - [12/Jan/2024 14:04:42] "POST /AddGraphData HTTP/1.1" 200 -
[36mflask-rest-api |[0m INFO:werkzeug:141.87.60.118 - - [12/Jan/2024 14:04:45] "GET /GetGraphData HTTP/1.1" 200 -
[33mlocal_db   |[0m 2024-01-12 14:06:08.409 UTC [27] LOG:  checkpoint starting: time
[33mlocal_db   |[0m 2024-01-12 14:06:08.778 UTC [27] LOG:  checkpoint complete: wrote 4 buffers (0.0%); 0 WAL file(s) added, 0 removed, 0 recycled; write=0.321 s, sync=0.010 s, total=0.370 s; sync files=4, longest=0.008 s, average=0.003 s; distance=3 kB, estimate=3 kB; lsn=0/1951C58, redo lsn=0/1951C20
[36mflask-rest-api |[0m INFO:werkzeug:141.87.60.118 - - [12/Jan/2024 14:08:23] "POST /AddGraphData HTTP/1.1" 200 -
[36mflask-rest-api |[0m INFO:werkzeug:141.87.60.118 - - [12/Jan/2024 14:08:42] "GET /GetGraphData HTTP/1.1" 200 -
[33mlocal_db   |[0m 2024-01-12 14:11:08.833 UTC [27] LOG:  checkpoint starting: time
[33mlocal_db   |[0m 2024-01-12 14:11:09.447 UTC [27] LOG:  checkpoint complete: wrote 4 buffers (0.0%); 0 WAL file(s) added, 0 removed, 0 recycled; write=0.396 s, sync=0.053 s, total=0.615 s; sync files=4, longest=0.052 s, average=0.014 s; distance=3 kB, estimate=3 kB; lsn=0/1952A88, redo lsn=0/1952A50
[32mscanner    |[0m /usr/lib/python3.11/site-packages/urllib3/connectionpool.py:1099: InsecureRequestWarning: Unverified HTTPS request is being made to host '0.0.0.0'. Adding certificate verification is strongly advised. See: https://urllib3.readthedocs.io/en/latest/advanced-usage.html#tls-warnings
[32mscanner    |[0m   warnings.warn(
[36mflask-rest-api |[0m INFO:werkzeug:172.18.0.1 - - [12/Jan/2024 15:00:10] "POST /AddGraphData HTTP/1.1" 200 -
[32mscanner    |[0m arp-scan ran successfully.
[32mscanner    |[0m Traceback (most recent call last):
[32mscanner    |[0m   File "/usr/lib/python3.11/site-packages/urllib3/connectionpool.py", line 467, in _make_request
[32mscanner    |[0m     self._validate_conn(conn)
[32mscanner    |[0m   File "/usr/lib/python3.11/site-packages/urllib3/connectionpool.py", line 1096, in _validate_conn
[32mscanner    |[0m     conn.connect()
[32mscanner    |[0m   File "/usr/lib/python3.11/site-packages/urllib3/connection.py", line 642, in connect
[32mscanner    |[0m     sock_and_verified = _ssl_wrap_socket_and_match_hostname(
[32mscanner    |[0m                         ^^^^^^^^^^^^^^^^^^^^^^^^^^^^^^^^^^^^
[32mscanner    |[0m   File "/usr/lib/python3.11/site-packages/urllib3/connection.py", line 782, in _ssl_wrap_socket_and_match_hostname
[32mscanner    |[0m     ssl_sock = ssl_wrap_socket(
[32mscanner    |[0m                ^^^^^^^^^^^^^^^^
[32mscanner    |[0m   File "/usr/lib/python3.11/site-packages/urllib3/util/ssl_.py", line 470, in ssl_wrap_socket
[32mscanner    |[0m     ssl_sock = _ssl_wrap_socket_impl(sock, context, tls_in_tls, server_hostname)
[32mscanner    |[0m                ^^^^^^^^^^^^^^^^^^^^^^^^^^^^^^^^^^^^^^^^^^^^^^^^^^^^^^^^^^^^^^^^^
[32mscanner    |[0m   File "/usr/lib/python3.11/site-packages/urllib3/util/ssl_.py", line 514, in _ssl_wrap_socket_impl
[32mscanner    |[0m     return ssl_context.wrap_socket(sock, server_hostname=server_hostname)
[32mscanner    |[0m            ^^^^^^^^^^^^^^^^^^^^^^^^^^^^^^^^^^^^^^^^^^^^^^^^^^^^^^^^^^^^^^
[32mscanner    |[0m   File "/usr/lib/python3.11/ssl.py", line 517, in wrap_socket
[32mscanner    |[0m     return self.sslsocket_class._create(
[32mscanner    |[0m            ^^^^^^^^^^^^^^^^^^^^^^^^^^^^^
[32mscanner    |[0m   File "/usr/lib/python3.11/ssl.py", line 1108, in _create
[32mscanner    |[0m     self.do_handshake()
[32mscanner    |[0m   File "/usr/lib/python3.11/ssl.py", line 1379, in do_handshake
[32mscanner    |[0m     self._sslobj.do_handshake()
[32mscanner    |[0m ssl.SSLCertVerificationError: [SSL: CERTIFICATE_VERIFY_FAILED] certificate verify failed: self-signed certificate (_ssl.c:1006)
[32mscanner    |[0m 
[32mscanner    |[0m During handling of the above exception, another exception occurred:
[32mscanner    |[0m 
[32mscanner    |[0m Traceback (most recent call last):
[32mscanner    |[0m   File "/usr/lib/python3.11/site-packages/urllib3/connectionpool.py", line 790, in urlopen
[32mscanner    |[0m     response = self._make_request(
[32mscanner    |[0m                ^^^^^^^^^^^^^^^^^^^
[32mscanner    |[0m   File "/usr/lib/python3.11/site-packages/urllib3/connectionpool.py", line 491, in _make_request
[32mscanner    |[0m     raise new_e
[32mscanner    |[0m urllib3.exceptions.SSLError: [SSL: CERTIFICATE_VERIFY_FAILED] certificate verify failed: self-signed certificate (_ssl.c:1006)
[32mscanner    |[0m 
[32mscanner    |[0m The above exception was the direct cause of the following exception:
[32mscanner    |[0m 
[32mscanner    |[0m Traceback (most recent call last):
[32mscanner    |[0m   File "/usr/lib/python3.11/site-packages/requests/adapters.py", line 486, in send
[32mscanner    |[0m     resp = conn.urlopen(
[32mscanner    |[0m            ^^^^^^^^^^^^^
[32mscanner    |[0m   File "/usr/lib/python3.11/site-packages/urllib3/connectionpool.py", line 844, in urlopen
[32mscanner    |[0m     retries = retries.increment(
[32mscanner    |[0m               ^^^^^^^^^^^^^^^^^^
[32mscanner    |[0m   File "/usr/lib/python3.11/site-packages/urllib3/util/retry.py", line 515, in increment
[32mscanner    |[0m     raise MaxRetryError(_pool, url, reason) from reason  # type: ignore[arg-type]
[32mscanner    |[0m     ^^^^^^^^^^^^^^^^^^^^^^^^^^^^^^^^^^^^^^^^^^^^^^^^^^^
[32mscanner    |[0m urllib3.exceptions.MaxRetryError: HTTPSConnectionPool(host='0.0.0.0', port=5000): Max retries exceeded with url: /AddGraphData (Caused by SSLError(SSLCertVerificationError(1, '[SSL: CERTIFICATE_VERIFY_FAILED] certificate verify failed: self-signed certificate (_ssl.c:1006)')))
[32mscanner    |[0m 
[32mscanner    |[0m During handling of the above exception, another exception occurred:
[32mscanner    |[0m 
[32mscanner    |[0m Traceback (most recent call last):
[32mscanner    |[0m   File "/app/scanner.py", line 95, in <module>
[32mscanner    |[0m     schedule.run_pending()
[32mscanner    |[0m   File "/usr/lib/python3.11/site-packages/schedule/__init__.py", line 822, in run_pending
[32mscanner    |[0m     default_scheduler.run_pending()
[32mscanner    |[0m   File "/usr/lib/python3.11/site-packages/schedule/__init__.py", line 100, in run_pending
[32mscanner    |[0m     self._run_job(job)
[32mscanner    |[0m   File "/usr/lib/python3.11/site-packages/schedule/__init__.py", line 172, in _run_job
[32mscanner    |[0m     ret = job.run()
[32mscanner    |[0m           ^^^^^^^^^
[32mscanner    |[0m   File "/usr/lib/python3.11/site-packages/schedule/__init__.py", line 693, in run
[32mscanner    |[0m     ret = self.job_func()
[32mscanner    |[0m           ^^^^^^^^^^^^^^^
[32mscanner    |[0m   File "/app/scanner.py", line 66, in scan
[32mscanner    |[0m     response = requests.post(url, json=data)
[32mscanner    |[0m                ^^^^^^^^^^^^^^^^^^^^^^^^^^^^^
[32mscanner    |[0m   File "/usr/lib/python3.11/site-packages/requests/api.py", line 115, in post
[32mscanner    |[0m     return request("post", url, data=data, json=json, **kwargs)
[32mscanner    |[0m            ^^^^^^^^^^^^^^^^^^^^^^^^^^^^^^^^^^^^^^^^^^^^^^^^^^^^
[32mscanner    |[0m   File "/usr/lib/python3.11/site-packages/requests/api.py", line 59, in request
[32mscanner    |[0m     return session.request(method=method, url=url, **kwargs)
[32mscanner    |[0m            ^^^^^^^^^^^^^^^^^^^^^^^^^^^^^^^^^^^^^^^^^^^^^^^^^
[32mscanner    |[0m   File "/usr/lib/python3.11/site-packages/requests/sessions.py", line 589, in request
[32mscanner    |[0m     resp = self.send(prep, **send_kwargs)
[32mscanner    |[0m            ^^^^^^^^^^^^^^^^^^^^^^^^^^^^^^
[32mscanner    |[0m   File "/usr/lib/python3.11/site-packages/requests/sessions.py", line 703, in send
[32mscanner    |[0m     r = adapter.send(request, **kwargs)
[32mscanner    |[0m         ^^^^^^^^^^^^^^^^^^^^^^^^^^^^^^^
[32mscanner    |[0m   File "/usr/lib/python3.11/site-packages/requests/adapters.py", line 517, in send
[32mscanner    |[0m     raise SSLError(e, request=request)
[32mscanner    |[0m requests.exceptions.SSLError: HTTPSConnectionPool(host='0.0.0.0', port=5000): Max retries exceeded with url: /AddGraphData (Caused by SSLError(SSLCertVerificationError(1, '[SSL: CERTIFICATE_VERIFY_FAILED] certificate verify failed: self-signed certificate (_ssl.c:1006)')))
[32mscanner exited with code 1
[0m[33mlocal_db   |[0m 2024-01-12 15:01:09.024 UTC [27] LOG:  checkpoint starting: time
[33mlocal_db   |[0m 2024-01-12 15:01:09.369 UTC [27] LOG:  checkpoint complete: wrote 4 buffers (0.0%); 0 WAL file(s) added, 0 removed, 0 recycled; write=0.312 s, sync=0.011 s, total=0.346 s; sync files=4, longest=0.009 s, average=0.003 s; distance=3 kB, estimate=3 kB; lsn=0/1953930, redo lsn=0/19538F8
[36mflask-rest-api |[0m INFO:werkzeug:141.87.60.118 - - [12/Jan/2024 19:09:52] "GET /GetGraphData HTTP/1.1" 200 -
[36mflask-rest-api exited with code 0
[0m[35mflask-rest-api |[0m  * Serving Flask app 'RestService' (lazy loading)
[35mflask-rest-api |[0m  * Environment: production
[35mflask-rest-api |[0m    WARNING: This is a development server. Do not use it in a production deployment.
[35mflask-rest-api |[0m    Use a production WSGI server instead.
[35mflask-rest-api |[0m  * Debug mode: on
[35mflask-rest-api |[0m WARNING:werkzeug: * Running on all addresses.
[35mflask-rest-api |[0m    WARNING: This is a development server. Do not use it in a production deployment.
[35mflask-rest-api |[0m INFO:werkzeug: * Running on https://172.18.0.3:5000/ (Press CTRL+C to quit)
[35mflask-rest-api |[0m INFO:werkzeug: * Restarting with stat
[35mflask-rest-api |[0m WARNING:werkzeug: * Debugger is active!
[35mflask-rest-api |[0m INFO:werkzeug: * Debugger PIN: 135-005-259
[34mscanner    |[0m /usr/lib/python3.11/site-packages/urllib3/connectionpool.py:1099: InsecureRequestWarning: Unverified HTTPS request is being made to host '0.0.0.0'. Adding certificate verification is strongly advised. See: https://urllib3.readthedocs.io/en/latest/advanced-usage.html#tls-warnings
[34mscanner    |[0m   warnings.warn(
[35mflask-rest-api |[0m INFO:werkzeug:172.18.0.1 - - [13/Jan/2024 16:45:11] "POST /AddGraphData HTTP/1.1" 200 -
[34mscanner    |[0m /usr/lib/python3.11/site-packages/urllib3/connectionpool.py:1099: InsecureRequestWarning: Unverified HTTPS request is being made to host '0.0.0.0'. Adding certificate verification is strongly advised. See: https://urllib3.readthedocs.io/en/latest/advanced-usage.html#tls-warnings
[34mscanner    |[0m   warnings.warn(
[33mlocal_db   |[0m 2024-01-13 16:45:11.598 UTC [2793] ERROR:  column "hashed_mac_address" of relation "mac_addresses" does not exist at character 40
[33mlocal_db   |[0m 2024-01-13 16:45:11.598 UTC [2793] STATEMENT:  INSERT INTO mac_addresses (time_stamp, hashed_mac_address) VALUES (1705164310, 'bd7e07507a3fe4ffc97b08454e0156c81c8062f1f0e0b5b330ab2a3aedb5c9cd')
[35mflask-rest-api |[0m INFO:werkzeug:172.18.0.1 - - [13/Jan/2024 16:45:11] "POST /AddGraphData HTTP/1.1" 200 -
[34mscanner    |[0m /usr/lib/python3.11/site-packages/urllib3/connectionpool.py:1099: InsecureRequestWarning: Unverified HTTPS request is being made to host '0.0.0.0'. Adding certificate verification is strongly advised. See: https://urllib3.readthedocs.io/en/latest/advanced-usage.html#tls-warnings
[34mscanner    |[0m   warnings.warn(
[33mlocal_db   |[0m 2024-01-13 16:45:11.876 UTC [2794] ERROR:  column "hashed_mac_address" of relation "mac_addresses" does not exist at character 40
[33mlocal_db   |[0m 2024-01-13 16:45:11.876 UTC [2794] STATEMENT:  INSERT INTO mac_addresses (time_stamp, hashed_mac_address) VALUES (1705164310, '0084c490512f10feee89f3bfb2abc6c562f57b4f245010219ea92618baf34fd2')
[35mflask-rest-api |[0m INFO:werkzeug:172.18.0.1 - - [13/Jan/2024 16:45:11] "POST /AddGraphData HTTP/1.1" 200 -
[34mscanner    |[0m /usr/lib/python3.11/site-packages/urllib3/connectionpool.py:1099: InsecureRequestWarning: Unverified HTTPS request is being made to host '0.0.0.0'. Adding certificate verification is strongly advised. See: https://urllib3.readthedocs.io/en/latest/advanced-usage.html#tls-warnings
[34mscanner    |[0m   warnings.warn(
[33mlocal_db   |[0m 2024-01-13 16:45:12.155 UTC [2795] ERROR:  column "hashed_mac_address" of relation "mac_addresses" does not exist at character 40
[33mlocal_db   |[0m 2024-01-13 16:45:12.155 UTC [2795] STATEMENT:  INSERT INTO mac_addresses (time_stamp, hashed_mac_address) VALUES (1705164310, 'efc11f20e6d98f6b5f62dba6167c1422d426206832f1ac69225ef16086ed1061')
[35mflask-rest-api |[0m INFO:werkzeug:172.18.0.1 - - [13/Jan/2024 16:45:12] "POST /AddGraphData HTTP/1.1" 200 -
[34mscanner    |[0m /usr/lib/python3.11/site-packages/urllib3/connectionpool.py:1099: InsecureRequestWarning: Unverified HTTPS request is being made to host '0.0.0.0'. Adding certificate verification is strongly advised. See: https://urllib3.readthedocs.io/en/latest/advanced-usage.html#tls-warnings
[34mscanner    |[0m   warnings.warn(
[33mlocal_db   |[0m 2024-01-13 16:45:12.431 UTC [2796] ERROR:  column "hashed_mac_address" of relation "mac_addresses" does not exist at character 40
[33mlocal_db   |[0m 2024-01-13 16:45:12.431 UTC [2796] STATEMENT:  INSERT INTO mac_addresses (time_stamp, hashed_mac_address) VALUES (1705164310, '0084c490512f10feee89f3bfb2abc6c562f57b4f245010219ea92618baf34fd2')
[35mflask-rest-api |[0m INFO:werkzeug:172.18.0.1 - - [13/Jan/2024 16:45:12] "POST /AddGraphData HTTP/1.1" 200 -
[34mscanner    |[0m /usr/lib/python3.11/site-packages/urllib3/connectionpool.py:1099: InsecureRequestWarning: Unverified HTTPS request is being made to host '0.0.0.0'. Adding certificate verification is strongly advised. See: https://urllib3.readthedocs.io/en/latest/advanced-usage.html#tls-warnings
[34mscanner    |[0m   warnings.warn(
[33mlocal_db   |[0m 2024-01-13 16:45:12.709 UTC [2797] ERROR:  column "hashed_mac_address" of relation "mac_addresses" does not exist at character 40
[33mlocal_db   |[0m 2024-01-13 16:45:12.709 UTC [2797] STATEMENT:  INSERT INTO mac_addresses (time_stamp, hashed_mac_address) VALUES (1705164310, '3f9b8645127d2ef655c97df5621c6d49ef2a3c899b41c89df96dd1f4914cea5f')
[35mflask-rest-api |[0m INFO:werkzeug:172.18.0.1 - - [13/Jan/2024 16:45:12] "POST /AddGraphData HTTP/1.1" 200 -
[34mscanner    |[0m /usr/lib/python3.11/site-packages/urllib3/connectionpool.py:1099: InsecureRequestWarning: Unverified HTTPS request is being made to host '0.0.0.0'. Adding certificate verification is strongly advised. See: https://urllib3.readthedocs.io/en/latest/advanced-usage.html#tls-warnings
[34mscanner    |[0m   warnings.warn(
[33mlocal_db   |[0m 2024-01-13 16:45:12.987 UTC [2798] ERROR:  column "hashed_mac_address" of relation "mac_addresses" does not exist at character 40
[33mlocal_db   |[0m 2024-01-13 16:45:12.987 UTC [2798] STATEMENT:  INSERT INTO mac_addresses (time_stamp, hashed_mac_address) VALUES (1705164310, '0084c490512f10feee89f3bfb2abc6c562f57b4f245010219ea92618baf34fd2')
[35mflask-rest-api |[0m INFO:werkzeug:172.18.0.1 - - [13/Jan/2024 16:45:12] "POST /AddGraphData HTTP/1.1" 200 -
[34mscanner    |[0m /usr/lib/python3.11/site-packages/urllib3/connectionpool.py:1099: InsecureRequestWarning: Unverified HTTPS request is being made to host '0.0.0.0'. Adding certificate verification is strongly advised. See: https://urllib3.readthedocs.io/en/latest/advanced-usage.html#tls-warnings
[34mscanner    |[0m   warnings.warn(
[33mlocal_db   |[0m 2024-01-13 16:45:13.260 UTC [2799] ERROR:  column "hashed_mac_address" of relation "mac_addresses" does not exist at character 40
[33mlocal_db   |[0m 2024-01-13 16:45:13.260 UTC [2799] STATEMENT:  INSERT INTO mac_addresses (time_stamp, hashed_mac_address) VALUES (1705164310, 'eb75bf378c1c44b96dfdef4c675ebcaa8b827ebb7aa5bc53e4f99e5dd79437d8')
[35mflask-rest-api |[0m INFO:werkzeug:172.18.0.1 - - [13/Jan/2024 16:45:13] "POST /AddGraphData HTTP/1.1" 200 -
[34mscanner    |[0m /usr/lib/python3.11/site-packages/urllib3/connectionpool.py:1099: InsecureRequestWarning: Unverified HTTPS request is being made to host '0.0.0.0'. Adding certificate verification is strongly advised. See: https://urllib3.readthedocs.io/en/latest/advanced-usage.html#tls-warnings
[34mscanner    |[0m   warnings.warn(
[33mlocal_db   |[0m 2024-01-13 16:45:13.530 UTC [2800] ERROR:  column "hashed_mac_address" of relation "mac_addresses" does not exist at character 40
[33mlocal_db   |[0m 2024-01-13 16:45:13.530 UTC [2800] STATEMENT:  INSERT INTO mac_addresses (time_stamp, hashed_mac_address) VALUES (1705164310, '0084c490512f10feee89f3bfb2abc6c562f57b4f245010219ea92618baf34fd2')
[35mflask-rest-api |[0m INFO:werkzeug:172.18.0.1 - - [13/Jan/2024 16:45:13] "POST /AddGraphData HTTP/1.1" 200 -
[34mscanner    |[0m /usr/lib/python3.11/site-packages/urllib3/connectionpool.py:1099: InsecureRequestWarning: Unverified HTTPS request is being made to host '0.0.0.0'. Adding certificate verification is strongly advised. See: https://urllib3.readthedocs.io/en/latest/advanced-usage.html#tls-warnings
[34mscanner    |[0m   warnings.warn(
[33mlocal_db   |[0m 2024-01-13 16:45:13.798 UTC [2801] ERROR:  column "hashed_mac_address" of relation "mac_addresses" does not exist at character 40
[33mlocal_db   |[0m 2024-01-13 16:45:13.798 UTC [2801] STATEMENT:  INSERT INTO mac_addresses (time_stamp, hashed_mac_address) VALUES (1705164310, 'bf66da5dfba0a812254de2a8ebc17cd6b3b16e60cf0896e31c95157e26fcf343')
[35mflask-rest-api |[0m INFO:werkzeug:172.18.0.1 - - [13/Jan/2024 16:45:13] "POST /AddGraphData HTTP/1.1" 200 -
[34mscanner    |[0m /usr/lib/python3.11/site-packages/urllib3/connectionpool.py:1099: InsecureRequestWarning: Unverified HTTPS request is being made to host '0.0.0.0'. Adding certificate verification is strongly advised. See: https://urllib3.readthedocs.io/en/latest/advanced-usage.html#tls-warnings
[34mscanner    |[0m   warnings.warn(
[33mlocal_db   |[0m 2024-01-13 16:45:14.072 UTC [2802] ERROR:  column "hashed_mac_address" of relation "mac_addresses" does not exist at character 40
[33mlocal_db   |[0m 2024-01-13 16:45:14.072 UTC [2802] STATEMENT:  INSERT INTO mac_addresses (time_stamp, hashed_mac_address) VALUES (1705164310, '0084c490512f10feee89f3bfb2abc6c562f57b4f245010219ea92618baf34fd2')
[35mflask-rest-api |[0m INFO:werkzeug:172.18.0.1 - - [13/Jan/2024 16:45:14] "POST /AddGraphData HTTP/1.1" 200 -
[34mscanner    |[0m /usr/lib/python3.11/site-packages/urllib3/connectionpool.py:1099: InsecureRequestWarning: Unverified HTTPS request is being made to host '0.0.0.0'. Adding certificate verification is strongly advised. See: https://urllib3.readthedocs.io/en/latest/advanced-usage.html#tls-warnings
[34mscanner    |[0m   warnings.warn(
[33mlocal_db   |[0m 2024-01-13 16:45:14.344 UTC [2803] ERROR:  column "hashed_mac_address" of relation "mac_addresses" does not exist at character 40
[33mlocal_db   |[0m 2024-01-13 16:45:14.344 UTC [2803] STATEMENT:  INSERT INTO mac_addresses (time_stamp, hashed_mac_address) VALUES (1705164310, '048511c8740c7687a7fbadd8866d3801155c2b4a9510a6c639cc15d920043988')
[35mflask-rest-api |[0m INFO:werkzeug:172.18.0.1 - - [13/Jan/2024 16:45:14] "POST /AddGraphData HTTP/1.1" 200 -
[34mscanner    |[0m /usr/lib/python3.11/site-packages/urllib3/connectionpool.py:1099: InsecureRequestWarning: Unverified HTTPS request is being made to host '0.0.0.0'. Adding certificate verification is strongly advised. See: https://urllib3.readthedocs.io/en/latest/advanced-usage.html#tls-warnings
[34mscanner    |[0m   warnings.warn(
[33mlocal_db   |[0m 2024-01-13 16:45:14.617 UTC [2804] ERROR:  column "hashed_mac_address" of relation "mac_addresses" does not exist at character 40
[33mlocal_db   |[0m 2024-01-13 16:45:14.617 UTC [2804] STATEMENT:  INSERT INTO mac_addresses (time_stamp, hashed_mac_address) VALUES (1705164310, '0084c490512f10feee89f3bfb2abc6c562f57b4f245010219ea92618baf34fd2')
[35mflask-rest-api |[0m INFO:werkzeug:172.18.0.1 - - [13/Jan/2024 16:45:14] "POST /AddGraphData HTTP/1.1" 200 -
[34mscanner    |[0m /usr/lib/python3.11/site-packages/urllib3/connectionpool.py:1099: InsecureRequestWarning: Unverified HTTPS request is being made to host '0.0.0.0'. Adding certificate verification is strongly advised. See: https://urllib3.readthedocs.io/en/latest/advanced-usage.html#tls-warnings
[34mscanner    |[0m   warnings.warn(
[33mlocal_db   |[0m 2024-01-13 16:45:14.891 UTC [2805] ERROR:  column "hashed_mac_address" of relation "mac_addresses" does not exist at character 40
[33mlocal_db   |[0m 2024-01-13 16:45:14.891 UTC [2805] STATEMENT:  INSERT INTO mac_addresses (time_stamp, hashed_mac_address) VALUES (1705164310, '9b5ef541b63e91331ec5a40eefe227e733d364fd62abb7098736a04d184f0b56')
[35mflask-rest-api |[0m INFO:werkzeug:172.18.0.1 - - [13/Jan/2024 16:45:14] "POST /AddGraphData HTTP/1.1" 200 -
[34mscanner    |[0m /usr/lib/python3.11/site-packages/urllib3/connectionpool.py:1099: InsecureRequestWarning: Unverified HTTPS request is being made to host '0.0.0.0'. Adding certificate verification is strongly advised. See: https://urllib3.readthedocs.io/en/latest/advanced-usage.html#tls-warnings
[34mscanner    |[0m   warnings.warn(
[33mlocal_db   |[0m 2024-01-13 16:45:15.161 UTC [2806] ERROR:  column "hashed_mac_address" of relation "mac_addresses" does not exist at character 40
[33mlocal_db   |[0m 2024-01-13 16:45:15.161 UTC [2806] STATEMENT:  INSERT INTO mac_addresses (time_stamp, hashed_mac_address) VALUES (1705164310, '0084c490512f10feee89f3bfb2abc6c562f57b4f245010219ea92618baf34fd2')
[35mflask-rest-api |[0m INFO:werkzeug:172.18.0.1 - - [13/Jan/2024 16:45:15] "POST /AddGraphData HTTP/1.1" 200 -
[34mscanner    |[0m /usr/lib/python3.11/site-packages/urllib3/connectionpool.py:1099: InsecureRequestWarning: Unverified HTTPS request is being made to host '0.0.0.0'. Adding certificate verification is strongly advised. See: https://urllib3.readthedocs.io/en/latest/advanced-usage.html#tls-warnings
[34mscanner    |[0m   warnings.warn(
[33mlocal_db   |[0m 2024-01-13 16:45:15.435 UTC [2807] ERROR:  column "hashed_mac_address" of relation "mac_addresses" does not exist at character 40
[33mlocal_db   |[0m 2024-01-13 16:45:15.435 UTC [2807] STATEMENT:  INSERT INTO mac_addresses (time_stamp, hashed_mac_address) VALUES (1705164310, '50c5cf8963fb314d80146ff6b656814d329d12f4fa7ef86490a86d0c807eb3f9')
[35mflask-rest-api |[0m INFO:werkzeug:172.18.0.1 - - [13/Jan/2024 16:45:15] "POST /AddGraphData HTTP/1.1" 200 -
[34mscanner    |[0m /usr/lib/python3.11/site-packages/urllib3/connectionpool.py:1099: InsecureRequestWarning: Unverified HTTPS request is being made to host '0.0.0.0'. Adding certificate verification is strongly advised. See: https://urllib3.readthedocs.io/en/latest/advanced-usage.html#tls-warnings
[34mscanner    |[0m   warnings.warn(
[35mflask-rest-api |[0m INFO:werkzeug:172.18.0.1 - - [13/Jan/2024 16:45:15] "POST /AddGraphData HTTP/1.1" 200 -
[33mlocal_db   |[0m 2024-01-13 16:45:15.706 UTC [2808] ERROR:  column "hashed_mac_address" of relation "mac_addresses" does not exist at character 40
[33mlocal_db   |[0m 2024-01-13 16:45:15.706 UTC [2808] STATEMENT:  INSERT INTO mac_addresses (time_stamp, hashed_mac_address) VALUES (1705164310, '0084c490512f10feee89f3bfb2abc6c562f57b4f245010219ea92618baf34fd2')
[34mscanner    |[0m /usr/lib/python3.11/site-packages/urllib3/connectionpool.py:1099: InsecureRequestWarning: Unverified HTTPS request is being made to host '0.0.0.0'. Adding certificate verification is strongly advised. See: https://urllib3.readthedocs.io/en/latest/advanced-usage.html#tls-warnings
[34mscanner    |[0m   warnings.warn(
[33mlocal_db   |[0m 2024-01-13 16:45:16.016 UTC [2809] ERROR:  column "hashed_mac_address" of relation "mac_addresses" does not exist at character 40
[33mlocal_db   |[0m 2024-01-13 16:45:16.016 UTC [2809] STATEMENT:  INSERT INTO mac_addresses (time_stamp, hashed_mac_address) VALUES (1705164310, 'c2c8ac7ec0e1ddcd3641c3abeb65d8133395526bbbd1094461ed3e30a0f0914b')
[35mflask-rest-api |[0m INFO:werkzeug:172.18.0.1 - - [13/Jan/2024 16:45:16] "POST /AddGraphData HTTP/1.1" 200 -
[34mscanner    |[0m /usr/lib/python3.11/site-packages/urllib3/connectionpool.py:1099: InsecureRequestWarning: Unverified HTTPS request is being made to host '0.0.0.0'. Adding certificate verification is strongly advised. See: https://urllib3.readthedocs.io/en/latest/advanced-usage.html#tls-warnings
[34mscanner    |[0m   warnings.warn(
[33mlocal_db   |[0m 2024-01-13 16:45:16.287 UTC [2810] ERROR:  column "hashed_mac_address" of relation "mac_addresses" does not exist at character 40
[33mlocal_db   |[0m 2024-01-13 16:45:16.287 UTC [2810] STATEMENT:  INSERT INTO mac_addresses (time_stamp, hashed_mac_address) VALUES (1705164310, '0084c490512f10feee89f3bfb2abc6c562f57b4f245010219ea92618baf34fd2')
[35mflask-rest-api |[0m INFO:werkzeug:172.18.0.1 - - [13/Jan/2024 16:45:16] "POST /AddGraphData HTTP/1.1" 200 -
[34mscanner    |[0m /usr/lib/python3.11/site-packages/urllib3/connectionpool.py:1099: InsecureRequestWarning: Unverified HTTPS request is being made to host '0.0.0.0'. Adding certificate verification is strongly advised. See: https://urllib3.readthedocs.io/en/latest/advanced-usage.html#tls-warnings
[34mscanner    |[0m   warnings.warn(
[33mlocal_db   |[0m 2024-01-13 16:45:16.563 UTC [2811] ERROR:  column "hashed_mac_address" of relation "mac_addresses" does not exist at character 40
[33mlocal_db   |[0m 2024-01-13 16:45:16.563 UTC [2811] STATEMENT:  INSERT INTO mac_addresses (time_stamp, hashed_mac_address) VALUES (1705164310, '775dc8ce9b9fdc8670e072e2fa5bb87b056f8c11c0818a9a97581a4c23616e93')
[35mflask-rest-api |[0m INFO:werkzeug:172.18.0.1 - - [13/Jan/2024 16:45:16] "POST /AddGraphData HTTP/1.1" 200 -
[34mscanner    |[0m /usr/lib/python3.11/site-packages/urllib3/connectionpool.py:1099: InsecureRequestWarning: Unverified HTTPS request is being made to host '0.0.0.0'. Adding certificate verification is strongly advised. See: https://urllib3.readthedocs.io/en/latest/advanced-usage.html#tls-warnings
[34mscanner    |[0m   warnings.warn(
[33mlocal_db   |[0m 2024-01-13 16:45:16.837 UTC [2812] ERROR:  column "hashed_mac_address" of relation "mac_addresses" does not exist at character 40
[33mlocal_db   |[0m 2024-01-13 16:45:16.837 UTC [2812] STATEMENT:  INSERT INTO mac_addresses (time_stamp, hashed_mac_address) VALUES (1705164310, '0084c490512f10feee89f3bfb2abc6c562f57b4f245010219ea92618baf34fd2')
[35mflask-rest-api |[0m INFO:werkzeug:172.18.0.1 - - [13/Jan/2024 16:45:16] "POST /AddGraphData HTTP/1.1" 200 -
[34mscanner    |[0m /usr/lib/python3.11/site-packages/urllib3/connectionpool.py:1099: InsecureRequestWarning: Unverified HTTPS request is being made to host '0.0.0.0'. Adding certificate verification is strongly advised. See: https://urllib3.readthedocs.io/en/latest/advanced-usage.html#tls-warnings
[34mscanner    |[0m   warnings.warn(
[33mlocal_db   |[0m 2024-01-13 16:45:17.105 UTC [2813] ERROR:  column "hashed_mac_address" of relation "mac_addresses" does not exist at character 40
[33mlocal_db   |[0m 2024-01-13 16:45:17.105 UTC [2813] STATEMENT:  INSERT INTO mac_addresses (time_stamp, hashed_mac_address) VALUES (1705164310, '8fce9020ff58468eeda05418d189755c02559d8be2bf2a38bea523e0c0d6f3e7')
[35mflask-rest-api |[0m INFO:werkzeug:172.18.0.1 - - [13/Jan/2024 16:45:17] "POST /AddGraphData HTTP/1.1" 200 -
[34mscanner    |[0m /usr/lib/python3.11/site-packages/urllib3/connectionpool.py:1099: InsecureRequestWarning: Unverified HTTPS request is being made to host '0.0.0.0'. Adding certificate verification is strongly advised. See: https://urllib3.readthedocs.io/en/latest/advanced-usage.html#tls-warnings
[34mscanner    |[0m   warnings.warn(
[33mlocal_db   |[0m 2024-01-13 16:45:17.376 UTC [2814] ERROR:  column "hashed_mac_address" of relation "mac_addresses" does not exist at character 40
[33mlocal_db   |[0m 2024-01-13 16:45:17.376 UTC [2814] STATEMENT:  INSERT INTO mac_addresses (time_stamp, hashed_mac_address) VALUES (1705164310, '0084c490512f10feee89f3bfb2abc6c562f57b4f245010219ea92618baf34fd2')
[35mflask-rest-api |[0m INFO:werkzeug:172.18.0.1 - - [13/Jan/2024 16:45:17] "POST /AddGraphData HTTP/1.1" 200 -
[34mscanner    |[0m /usr/lib/python3.11/site-packages/urllib3/connectionpool.py:1099: InsecureRequestWarning: Unverified HTTPS request is being made to host '0.0.0.0'. Adding certificate verification is strongly advised. See: https://urllib3.readthedocs.io/en/latest/advanced-usage.html#tls-warnings
[34mscanner    |[0m   warnings.warn(
[33mlocal_db   |[0m 2024-01-13 16:45:17.648 UTC [2815] ERROR:  column "hashed_mac_address" of relation "mac_addresses" does not exist at character 40
[33mlocal_db   |[0m 2024-01-13 16:45:17.648 UTC [2815] STATEMENT:  INSERT INTO mac_addresses (time_stamp, hashed_mac_address) VALUES (1705164310, 'c9b548f134e833666bb7dd9af239c7ecece9adb62d19d502290c2d31e9a24928')
[35mflask-rest-api |[0m INFO:werkzeug:172.18.0.1 - - [13/Jan/2024 16:45:17] "POST /AddGraphData HTTP/1.1" 200 -
[34mscanner    |[0m /usr/lib/python3.11/site-packages/urllib3/connectionpool.py:1099: InsecureRequestWarning: Unverified HTTPS request is being made to host '0.0.0.0'. Adding certificate verification is strongly advised. See: https://urllib3.readthedocs.io/en/latest/advanced-usage.html#tls-warnings
[34mscanner    |[0m   warnings.warn(
[33mlocal_db   |[0m 2024-01-13 16:45:17.923 UTC [2816] ERROR:  column "hashed_mac_address" of relation "mac_addresses" does not exist at character 40
[33mlocal_db   |[0m 2024-01-13 16:45:17.923 UTC [2816] STATEMENT:  INSERT INTO mac_addresses (time_stamp, hashed_mac_address) VALUES (1705164310, '0084c490512f10feee89f3bfb2abc6c562f57b4f245010219ea92618baf34fd2')
[35mflask-rest-api |[0m INFO:werkzeug:172.18.0.1 - - [13/Jan/2024 16:45:17] "POST /AddGraphData HTTP/1.1" 200 -
[34mscanner    |[0m /usr/lib/python3.11/site-packages/urllib3/connectionpool.py:1099: InsecureRequestWarning: Unverified HTTPS request is being made to host '0.0.0.0'. Adding certificate verification is strongly advised. See: https://urllib3.readthedocs.io/en/latest/advanced-usage.html#tls-warnings
[34mscanner    |[0m   warnings.warn(
[33mlocal_db   |[0m 2024-01-13 16:45:18.195 UTC [2817] ERROR:  column "hashed_mac_address" of relation "mac_addresses" does not exist at character 40
[33mlocal_db   |[0m 2024-01-13 16:45:18.195 UTC [2817] STATEMENT:  INSERT INTO mac_addresses (time_stamp, hashed_mac_address) VALUES (1705164310, '1105ac9e5014a985bb9def5b31a1d0c87f39c9158128de8ae35162deb1be0943')
[35mflask-rest-api |[0m INFO:werkzeug:172.18.0.1 - - [13/Jan/2024 16:45:18] "POST /AddGraphData HTTP/1.1" 200 -
[34mscanner    |[0m /usr/lib/python3.11/site-packages/urllib3/connectionpool.py:1099: InsecureRequestWarning: Unverified HTTPS request is being made to host '0.0.0.0'. Adding certificate verification is strongly advised. See: https://urllib3.readthedocs.io/en/latest/advanced-usage.html#tls-warnings
[34mscanner    |[0m   warnings.warn(
[33mlocal_db   |[0m 2024-01-13 16:45:18.467 UTC [2818] ERROR:  column "hashed_mac_address" of relation "mac_addresses" does not exist at character 40
[33mlocal_db   |[0m 2024-01-13 16:45:18.467 UTC [2818] STATEMENT:  INSERT INTO mac_addresses (time_stamp, hashed_mac_address) VALUES (1705164310, '0084c490512f10feee89f3bfb2abc6c562f57b4f245010219ea92618baf34fd2')
[35mflask-rest-api |[0m INFO:werkzeug:172.18.0.1 - - [13/Jan/2024 16:45:18] "POST /AddGraphData HTTP/1.1" 200 -
[34mscanner    |[0m /usr/lib/python3.11/site-packages/urllib3/connectionpool.py:1099: InsecureRequestWarning: Unverified HTTPS request is being made to host '0.0.0.0'. Adding certificate verification is strongly advised. See: https://urllib3.readthedocs.io/en/latest/advanced-usage.html#tls-warnings
[34mscanner    |[0m   warnings.warn(
[33mlocal_db   |[0m 2024-01-13 16:45:18.735 UTC [2819] ERROR:  column "hashed_mac_address" of relation "mac_addresses" does not exist at character 40
[33mlocal_db   |[0m 2024-01-13 16:45:18.735 UTC [2819] STATEMENT:  INSERT INTO mac_addresses (time_stamp, hashed_mac_address) VALUES (1705164310, '22b582fe7fb2278e2540d9944995a9dded18fb1da9d99d80575ee9d17e5d1bba')
[35mflask-rest-api |[0m INFO:werkzeug:172.18.0.1 - - [13/Jan/2024 16:45:18] "POST /AddGraphData HTTP/1.1" 200 -
[34mscanner    |[0m /usr/lib/python3.11/site-packages/urllib3/connectionpool.py:1099: InsecureRequestWarning: Unverified HTTPS request is being made to host '0.0.0.0'. Adding certificate verification is strongly advised. See: https://urllib3.readthedocs.io/en/latest/advanced-usage.html#tls-warnings
[34mscanner    |[0m   warnings.warn(
[33mlocal_db   |[0m 2024-01-13 16:45:19.007 UTC [2820] ERROR:  column "hashed_mac_address" of relation "mac_addresses" does not exist at character 40
[33mlocal_db   |[0m 2024-01-13 16:45:19.007 UTC [2820] STATEMENT:  INSERT INTO mac_addresses (time_stamp, hashed_mac_address) VALUES (1705164310, '0084c490512f10feee89f3bfb2abc6c562f57b4f245010219ea92618baf34fd2')
[35mflask-rest-api |[0m INFO:werkzeug:172.18.0.1 - - [13/Jan/2024 16:45:19] "POST /AddGraphData HTTP/1.1" 200 -
[34mscanner    |[0m /usr/lib/python3.11/site-packages/urllib3/connectionpool.py:1099: InsecureRequestWarning: Unverified HTTPS request is being made to host '0.0.0.0'. Adding certificate verification is strongly advised. See: https://urllib3.readthedocs.io/en/latest/advanced-usage.html#tls-warnings
[34mscanner    |[0m   warnings.warn(
[33mlocal_db   |[0m 2024-01-13 16:45:19.277 UTC [2821] ERROR:  column "hashed_mac_address" of relation "mac_addresses" does not exist at character 40
[33mlocal_db   |[0m 2024-01-13 16:45:19.277 UTC [2821] STATEMENT:  INSERT INTO mac_addresses (time_stamp, hashed_mac_address) VALUES (1705164310, '88dcdaebb05e5f2c823996e401285d5d503704a9980309dba87c21e06677f0ae')
[35mflask-rest-api |[0m INFO:werkzeug:172.18.0.1 - - [13/Jan/2024 16:45:19] "POST /AddGraphData HTTP/1.1" 200 -
[34mscanner    |[0m /usr/lib/python3.11/site-packages/urllib3/connectionpool.py:1099: InsecureRequestWarning: Unverified HTTPS request is being made to host '0.0.0.0'. Adding certificate verification is strongly advised. See: https://urllib3.readthedocs.io/en/latest/advanced-usage.html#tls-warnings
[34mscanner    |[0m   warnings.warn(
[33mlocal_db   |[0m 2024-01-13 16:45:19.547 UTC [2822] ERROR:  column "hashed_mac_address" of relation "mac_addresses" does not exist at character 40
[33mlocal_db   |[0m 2024-01-13 16:45:19.547 UTC [2822] STATEMENT:  INSERT INTO mac_addresses (time_stamp, hashed_mac_address) VALUES (1705164310, '0084c490512f10feee89f3bfb2abc6c562f57b4f245010219ea92618baf34fd2')
[35mflask-rest-api |[0m INFO:werkzeug:172.18.0.1 - - [13/Jan/2024 16:45:19] "POST /AddGraphData HTTP/1.1" 200 -
[34mscanner    |[0m /usr/lib/python3.11/site-packages/urllib3/connectionpool.py:1099: InsecureRequestWarning: Unverified HTTPS request is being made to host '0.0.0.0'. Adding certificate verification is strongly advised. See: https://urllib3.readthedocs.io/en/latest/advanced-usage.html#tls-warnings
[34mscanner    |[0m   warnings.warn(
[33mlocal_db   |[0m 2024-01-13 16:45:19.816 UTC [2823] ERROR:  column "hashed_mac_address" of relation "mac_addresses" does not exist at character 40
[33mlocal_db   |[0m 2024-01-13 16:45:19.816 UTC [2823] STATEMENT:  INSERT INTO mac_addresses (time_stamp, hashed_mac_address) VALUES (1705164310, '4fae096274a09eb333ed9993933fd662603f1154ea31a242ed52b5fb3a6eb5fd')
[35mflask-rest-api |[0m INFO:werkzeug:172.18.0.1 - - [13/Jan/2024 16:45:19] "POST /AddGraphData HTTP/1.1" 200 -
[34mscanner    |[0m /usr/lib/python3.11/site-packages/urllib3/connectionpool.py:1099: InsecureRequestWarning: Unverified HTTPS request is being made to host '0.0.0.0'. Adding certificate verification is strongly advised. See: https://urllib3.readthedocs.io/en/latest/advanced-usage.html#tls-warnings
[34mscanner    |[0m   warnings.warn(
[33mlocal_db   |[0m 2024-01-13 16:45:20.096 UTC [2824] ERROR:  column "hashed_mac_address" of relation "mac_addresses" does not exist at character 40
[33mlocal_db   |[0m 2024-01-13 16:45:20.096 UTC [2824] STATEMENT:  INSERT INTO mac_addresses (time_stamp, hashed_mac_address) VALUES (1705164310, '0084c490512f10feee89f3bfb2abc6c562f57b4f245010219ea92618baf34fd2')
[35mflask-rest-api |[0m INFO:werkzeug:172.18.0.1 - - [13/Jan/2024 16:45:20] "POST /AddGraphData HTTP/1.1" 200 -
[34mscanner    |[0m /usr/lib/python3.11/site-packages/urllib3/connectionpool.py:1099: InsecureRequestWarning: Unverified HTTPS request is being made to host '0.0.0.0'. Adding certificate verification is strongly advised. See: https://urllib3.readthedocs.io/en/latest/advanced-usage.html#tls-warnings
[34mscanner    |[0m   warnings.warn(
[33mlocal_db   |[0m 2024-01-13 16:45:20.365 UTC [2825] ERROR:  column "hashed_mac_address" of relation "mac_addresses" does not exist at character 40
[33mlocal_db   |[0m 2024-01-13 16:45:20.365 UTC [2825] STATEMENT:  INSERT INTO mac_addresses (time_stamp, hashed_mac_address) VALUES (1705164310, 'a6985f862581da884080ce5b2435bbf0ec84fa0fe5584ca848454d5fe776fbf9')
[35mflask-rest-api |[0m INFO:werkzeug:172.18.0.1 - - [13/Jan/2024 16:45:20] "POST /AddGraphData HTTP/1.1" 200 -
[34mscanner    |[0m /usr/lib/python3.11/site-packages/urllib3/connectionpool.py:1099: InsecureRequestWarning: Unverified HTTPS request is being made to host '0.0.0.0'. Adding certificate verification is strongly advised. See: https://urllib3.readthedocs.io/en/latest/advanced-usage.html#tls-warnings
[34mscanner    |[0m   warnings.warn(
[33mlocal_db   |[0m 2024-01-13 16:45:20.634 UTC [2826] ERROR:  column "hashed_mac_address" of relation "mac_addresses" does not exist at character 40
[33mlocal_db   |[0m 2024-01-13 16:45:20.634 UTC [2826] STATEMENT:  INSERT INTO mac_addresses (time_stamp, hashed_mac_address) VALUES (1705164310, '0084c490512f10feee89f3bfb2abc6c562f57b4f245010219ea92618baf34fd2')
[35mflask-rest-api |[0m INFO:werkzeug:172.18.0.1 - - [13/Jan/2024 16:45:20] "POST /AddGraphData HTTP/1.1" 200 -
[34mscanner    |[0m /usr/lib/python3.11/site-packages/urllib3/connectionpool.py:1099: InsecureRequestWarning: Unverified HTTPS request is being made to host '0.0.0.0'. Adding certificate verification is strongly advised. See: https://urllib3.readthedocs.io/en/latest/advanced-usage.html#tls-warnings
[34mscanner    |[0m   warnings.warn(
[33mlocal_db   |[0m 2024-01-13 16:45:20.907 UTC [2827] ERROR:  column "hashed_mac_address" of relation "mac_addresses" does not exist at character 40
[33mlocal_db   |[0m 2024-01-13 16:45:20.907 UTC [2827] STATEMENT:  INSERT INTO mac_addresses (time_stamp, hashed_mac_address) VALUES (1705164310, '8e63343cf78e7103791a708be513421e8498dcbf6fd93635d3358928c17ddb86')
[35mflask-rest-api |[0m INFO:werkzeug:172.18.0.1 - - [13/Jan/2024 16:45:20] "POST /AddGraphData HTTP/1.1" 200 -
[34mscanner    |[0m /usr/lib/python3.11/site-packages/urllib3/connectionpool.py:1099: InsecureRequestWarning: Unverified HTTPS request is being made to host '0.0.0.0'. Adding certificate verification is strongly advised. See: https://urllib3.readthedocs.io/en/latest/advanced-usage.html#tls-warnings
[34mscanner    |[0m   warnings.warn(
[33mlocal_db   |[0m 2024-01-13 16:45:21.216 UTC [2828] ERROR:  column "hashed_mac_address" of relation "mac_addresses" does not exist at character 40
[33mlocal_db   |[0m 2024-01-13 16:45:21.216 UTC [2828] STATEMENT:  INSERT INTO mac_addresses (time_stamp, hashed_mac_address) VALUES (1705164310, '0084c490512f10feee89f3bfb2abc6c562f57b4f245010219ea92618baf34fd2')
[35mflask-rest-api |[0m INFO:werkzeug:172.18.0.1 - - [13/Jan/2024 16:45:21] "POST /AddGraphData HTTP/1.1" 200 -
[34mscanner    |[0m /usr/lib/python3.11/site-packages/urllib3/connectionpool.py:1099: InsecureRequestWarning: Unverified HTTPS request is being made to host '0.0.0.0'. Adding certificate verification is strongly advised. See: https://urllib3.readthedocs.io/en/latest/advanced-usage.html#tls-warnings
[34mscanner    |[0m   warnings.warn(
[33mlocal_db   |[0m 2024-01-13 16:45:21.483 UTC [2829] ERROR:  column "hashed_mac_address" of relation "mac_addresses" does not exist at character 40
[33mlocal_db   |[0m 2024-01-13 16:45:21.483 UTC [2829] STATEMENT:  INSERT INTO mac_addresses (time_stamp, hashed_mac_address) VALUES (1705164310, 'c41219c63feeb02ee37120e997fc09628f72892cb14a1388ff7a1f49f3025f06')
[35mflask-rest-api |[0m INFO:werkzeug:172.18.0.1 - - [13/Jan/2024 16:45:21] "POST /AddGraphData HTTP/1.1" 200 -
[34mscanner    |[0m /usr/lib/python3.11/site-packages/urllib3/connectionpool.py:1099: InsecureRequestWarning: Unverified HTTPS request is being made to host '0.0.0.0'. Adding certificate verification is strongly advised. See: https://urllib3.readthedocs.io/en/latest/advanced-usage.html#tls-warnings
[34mscanner    |[0m   warnings.warn(
[33mlocal_db   |[0m 2024-01-13 16:45:21.749 UTC [2830] ERROR:  column "hashed_mac_address" of relation "mac_addresses" does not exist at character 40
[33mlocal_db   |[0m 2024-01-13 16:45:21.749 UTC [2830] STATEMENT:  INSERT INTO mac_addresses (time_stamp, hashed_mac_address) VALUES (1705164310, '0084c490512f10feee89f3bfb2abc6c562f57b4f245010219ea92618baf34fd2')
[35mflask-rest-api |[0m INFO:werkzeug:172.18.0.1 - - [13/Jan/2024 16:45:21] "POST /AddGraphData HTTP/1.1" 200 -
[34mscanner    |[0m /usr/lib/python3.11/site-packages/urllib3/connectionpool.py:1099: InsecureRequestWarning: Unverified HTTPS request is being made to host '0.0.0.0'. Adding certificate verification is strongly advised. See: https://urllib3.readthedocs.io/en/latest/advanced-usage.html#tls-warnings
[34mscanner    |[0m   warnings.warn(
[33mlocal_db   |[0m 2024-01-13 16:45:22.020 UTC [2831] ERROR:  column "hashed_mac_address" of relation "mac_addresses" does not exist at character 40
[33mlocal_db   |[0m 2024-01-13 16:45:22.020 UTC [2831] STATEMENT:  INSERT INTO mac_addresses (time_stamp, hashed_mac_address) VALUES (1705164310, '74a5e711c4f96ce5c332d3a93a6f4d0b405aad86adab0a7d64e16dd4d0222056')
[35mflask-rest-api |[0m INFO:werkzeug:172.18.0.1 - - [13/Jan/2024 16:45:22] "POST /AddGraphData HTTP/1.1" 200 -
[34mscanner    |[0m /usr/lib/python3.11/site-packages/urllib3/connectionpool.py:1099: InsecureRequestWarning: Unverified HTTPS request is being made to host '0.0.0.0'. Adding certificate verification is strongly advised. See: https://urllib3.readthedocs.io/en/latest/advanced-usage.html#tls-warnings
[34mscanner    |[0m   warnings.warn(
[33mlocal_db   |[0m 2024-01-13 16:45:22.289 UTC [2832] ERROR:  column "hashed_mac_address" of relation "mac_addresses" does not exist at character 40
[33mlocal_db   |[0m 2024-01-13 16:45:22.289 UTC [2832] STATEMENT:  INSERT INTO mac_addresses (time_stamp, hashed_mac_address) VALUES (1705164310, '0084c490512f10feee89f3bfb2abc6c562f57b4f245010219ea92618baf34fd2')
[35mflask-rest-api |[0m INFO:werkzeug:172.18.0.1 - - [13/Jan/2024 16:45:22] "POST /AddGraphData HTTP/1.1" 200 -
[34mscanner    |[0m /usr/lib/python3.11/site-packages/urllib3/connectionpool.py:1099: InsecureRequestWarning: Unverified HTTPS request is being made to host '0.0.0.0'. Adding certificate verification is strongly advised. See: https://urllib3.readthedocs.io/en/latest/advanced-usage.html#tls-warnings
[34mscanner    |[0m   warnings.warn(
[33mlocal_db   |[0m 2024-01-13 16:45:22.559 UTC [2833] ERROR:  column "hashed_mac_address" of relation "mac_addresses" does not exist at character 40
[33mlocal_db   |[0m 2024-01-13 16:45:22.559 UTC [2833] STATEMENT:  INSERT INTO mac_addresses (time_stamp, hashed_mac_address) VALUES (1705164310, 'a8f8b3096b00ec98247311f2b874a405209decfb06b934ab465ec6548a6adcc2')
[35mflask-rest-api |[0m INFO:werkzeug:172.18.0.1 - - [13/Jan/2024 16:45:22] "POST /AddGraphData HTTP/1.1" 200 -
[34mscanner    |[0m /usr/lib/python3.11/site-packages/urllib3/connectionpool.py:1099: InsecureRequestWarning: Unverified HTTPS request is being made to host '0.0.0.0'. Adding certificate verification is strongly advised. See: https://urllib3.readthedocs.io/en/latest/advanced-usage.html#tls-warnings
[34mscanner    |[0m   warnings.warn(
[33mlocal_db   |[0m 2024-01-13 16:45:22.829 UTC [2834] ERROR:  column "hashed_mac_address" of relation "mac_addresses" does not exist at character 40
[33mlocal_db   |[0m 2024-01-13 16:45:22.829 UTC [2834] STATEMENT:  INSERT INTO mac_addresses (time_stamp, hashed_mac_address) VALUES (1705164310, '0084c490512f10feee89f3bfb2abc6c562f57b4f245010219ea92618baf34fd2')
[35mflask-rest-api |[0m INFO:werkzeug:172.18.0.1 - - [13/Jan/2024 16:45:22] "POST /AddGraphData HTTP/1.1" 200 -
[34mscanner    |[0m /usr/lib/python3.11/site-packages/urllib3/connectionpool.py:1099: InsecureRequestWarning: Unverified HTTPS request is being made to host '0.0.0.0'. Adding certificate verification is strongly advised. See: https://urllib3.readthedocs.io/en/latest/advanced-usage.html#tls-warnings
[34mscanner    |[0m   warnings.warn(
[33mlocal_db   |[0m 2024-01-13 16:45:23.101 UTC [2835] ERROR:  column "hashed_mac_address" of relation "mac_addresses" does not exist at character 40
[33mlocal_db   |[0m 2024-01-13 16:45:23.101 UTC [2835] STATEMENT:  INSERT INTO mac_addresses (time_stamp, hashed_mac_address) VALUES (1705164310, '3ad0fb73d35ee24009c01fa0289d5e037ed6a65d6c5913e02b4ef07a4fdec5a1')
[35mflask-rest-api |[0m INFO:werkzeug:172.18.0.1 - - [13/Jan/2024 16:45:23] "POST /AddGraphData HTTP/1.1" 200 -
[34mscanner    |[0m /usr/lib/python3.11/site-packages/urllib3/connectionpool.py:1099: InsecureRequestWarning: Unverified HTTPS request is being made to host '0.0.0.0'. Adding certificate verification is strongly advised. See: https://urllib3.readthedocs.io/en/latest/advanced-usage.html#tls-warnings
[34mscanner    |[0m   warnings.warn(
[33mlocal_db   |[0m 2024-01-13 16:45:23.368 UTC [2836] ERROR:  column "hashed_mac_address" of relation "mac_addresses" does not exist at character 40
[33mlocal_db   |[0m 2024-01-13 16:45:23.368 UTC [2836] STATEMENT:  INSERT INTO mac_addresses (time_stamp, hashed_mac_address) VALUES (1705164310, '0084c490512f10feee89f3bfb2abc6c562f57b4f245010219ea92618baf34fd2')
[35mflask-rest-api |[0m INFO:werkzeug:172.18.0.1 - - [13/Jan/2024 16:45:23] "POST /AddGraphData HTTP/1.1" 200 -
[34mscanner    |[0m /usr/lib/python3.11/site-packages/urllib3/connectionpool.py:1099: InsecureRequestWarning: Unverified HTTPS request is being made to host '0.0.0.0'. Adding certificate verification is strongly advised. See: https://urllib3.readthedocs.io/en/latest/advanced-usage.html#tls-warnings
[34mscanner    |[0m   warnings.warn(
[33mlocal_db   |[0m 2024-01-13 16:45:23.638 UTC [2837] ERROR:  column "hashed_mac_address" of relation "mac_addresses" does not exist at character 40
[33mlocal_db   |[0m 2024-01-13 16:45:23.638 UTC [2837] STATEMENT:  INSERT INTO mac_addresses (time_stamp, hashed_mac_address) VALUES (1705164310, '75285b006b233382d4130c34a90ab77916b6dc52c3fedc36ff1b324efc8cc27e')
[35mflask-rest-api |[0m INFO:werkzeug:172.18.0.1 - - [13/Jan/2024 16:45:23] "POST /AddGraphData HTTP/1.1" 200 -
[34mscanner    |[0m /usr/lib/python3.11/site-packages/urllib3/connectionpool.py:1099: InsecureRequestWarning: Unverified HTTPS request is being made to host '0.0.0.0'. Adding certificate verification is strongly advised. See: https://urllib3.readthedocs.io/en/latest/advanced-usage.html#tls-warnings
[34mscanner    |[0m   warnings.warn(
[33mlocal_db   |[0m 2024-01-13 16:45:23.910 UTC [2838] ERROR:  column "hashed_mac_address" of relation "mac_addresses" does not exist at character 40
[33mlocal_db   |[0m 2024-01-13 16:45:23.910 UTC [2838] STATEMENT:  INSERT INTO mac_addresses (time_stamp, hashed_mac_address) VALUES (1705164310, '862bdb62b0bd441da13d3a4d92dd1d7ca82cc8d8158387d2cac69728b1de59e1')
[35mflask-rest-api |[0m INFO:werkzeug:172.18.0.1 - - [13/Jan/2024 16:45:23] "POST /AddGraphData HTTP/1.1" 200 -
[34mscanner    |[0m /usr/lib/python3.11/site-packages/urllib3/connectionpool.py:1099: InsecureRequestWarning: Unverified HTTPS request is being made to host '0.0.0.0'. Adding certificate verification is strongly advised. See: https://urllib3.readthedocs.io/en/latest/advanced-usage.html#tls-warnings
[34mscanner    |[0m   warnings.warn(
[33mlocal_db   |[0m 2024-01-13 16:45:24.180 UTC [2839] ERROR:  column "hashed_mac_address" of relation "mac_addresses" does not exist at character 40
[33mlocal_db   |[0m 2024-01-13 16:45:24.180 UTC [2839] STATEMENT:  INSERT INTO mac_addresses (time_stamp, hashed_mac_address) VALUES (1705164310, '0084c490512f10feee89f3bfb2abc6c562f57b4f245010219ea92618baf34fd2')
[35mflask-rest-api |[0m INFO:werkzeug:172.18.0.1 - - [13/Jan/2024 16:45:24] "POST /AddGraphData HTTP/1.1" 200 -
[33mlocal_db   |[0m 2024-01-13 16:46:30.223 UTC [27] LOG:  checkpoint starting: time
[33mlocal_db   |[0m 2024-01-13 16:46:30.598 UTC [27] LOG:  checkpoint complete: wrote 4 buffers (0.0%); 0 WAL file(s) added, 0 removed, 0 recycled; write=0.327 s, sync=0.011 s, total=0.375 s; sync files=4, longest=0.009 s, average=0.003 s; distance=3 kB, estimate=3 kB; lsn=0/1954880, redo lsn=0/1954848
[35mflask-rest-api |[0m INFO:werkzeug:141.87.60.118 - - [13/Jan/2024 17:07:54] "GET /GetGraphData HTTP/1.1" 200 -
